Workbook

Sheet CC_GAS-PROYX
B2: OBRA: EDIFICIO MULTIFAMILIAR EJEMPLO - TORRE 1
B3: COMPARATIVO - SISTEMA DE INSTALACIONES DE GAS
B4: FECHA: 26 DE OCTUBRE DEL 2026
B6: PRESUPUESTO META | H6: POSTOR A S.A.C. | K6: POSTOR B S.A.C. | N6: POSTOR C S.A.C.
B7: Descripción | C7: Unid | D7: Metrado | E7: P.Unitario (S/) | F7: P.Parcial (S/) | H7: Cant. | I7: P.Unitario (S/) | J7: P.Parcial (S/) | K7: Cant. | L7: P.Unitario (S/) | M7: P.Parcial (S/) | N7: Cant. | O7: P.Unitario (S/) | P7: P.Parcial (S/) | Q7: P.Unitario (S/) INC DSCTO 5.00% | R7: P.Parcial (S/) INC DSCTO 5.00%
B9: INSTALACIONES DE GAS | F9: =SUM(F11,F18,F25) | J9: =SUM(J11,J18,J25) | M9: =SUM(M11,M18,M25) | P9: =SUM(P11,P18,P25) | Q9: 0.05 | R9: =SUM(R11,R18,R25)
B11: INSTALACION EN LA RED MONTANTE | C11: glb | F11: =SUM(F13:F17) | H11: 1 | I11: 18000 | J11: =I11*H11 | M11: =SUM(M13:M17) | P11: =SUM(P13:P17) | R11: =SUM(R13:R17)
B13: Tubería Cu tipo L 3/4" vertical en ducto técnico | C13: m | F13: =E13*D13 | H13: Precio global de la montante (1 glb x S/ 18,000.00): incluye tubería de cobre, válvulas y prueba de hermeticidad, sin desagregar. | K13: 30 | L13: 90 | M13: =L13*K13 | N13: 25 | O13: 110 | P13: =O13*N13 | Q13: =O13*(1-$Q$9) | R13: =Q13*N13
B14: Tubería Cu tipo L 1" vertical en ducto técnico | C14: m | F14: =E14*D14 | K14: 40 | L14: 105 | M14: =L14*K14 | N14: 40 | O14: 140 | P14: =O14*N14 | Q14: =O14*(1-$Q$9) | R14: =Q14*N14
B15: Válvula de corte general de montante | C15: und | F15: =E15*D15 | N15: 1 | O15: 120 | P15: =O15*N15 | Q15: =O15*(1-$Q$9) | R15: =Q15*N15
B16: Pintura para tubería Cu en ducto técnico | C16: glb | F16: =E16*D16 | K16: 1 | L16: 600 | M16: =L16*K16
B17: Prueba de hermeticidad de línea montante | C17: glb | F17: =E17*D17 | K17: 1 | L17: 500 | M17: =L17*K17 | N17: 1 | O17: 650 | P17: =O17*N17 | Q17: =O17*(1-$Q$9) | R17: =Q17*N17
B18: INSTALACION DE LAS REDES INTERNAS | C18: dpto | F18: =SUM(F20:F24) | H18: 120 | I18: 900 | J18: =I18*H18 | M18: =SUM(M20:M24) | P18: =SUM(P20:P24) | R18: =SUM(R20:R24)
B20: Tubería PE-AL-PE 2025 empotrada en losa y muro | C20: m | F20: =E20*D20 | H20: Precio global por departamento (120 und x S/ 900.00): incluye tuberías PE-AL-PE, salidas, válvulas y pruebas, sin desagregar. | K20: 2000 | L20: 20 | M20: =L20*K20 | N20: 2300 | O20: 24 | P20: =O20*N20 | Q20: =O20*(1-$Q$9) | R20: =Q20*N20
B21: Tubería PE-AL-PE 1216 empotrada en losa y muro | C21: m | F21: =E21*D21 | K21: 2600 | L21: 18 | M21: =L21*K21 | N21: 2600 | O21: 19 | P21: =O21*N21 | Q21: =O21*(1-$Q$9) | R21: =Q21*N21
B22: Salidas para terma, cocina y horno | C22: pto | F22: =E22*D22 | K22: 360 | L22: 32 | M22: =L22*K22 | N22: 360 | O22: 30 | P22: =O22*N22 | Q22: =O22*(1-$Q$9) | R22: =Q22*N22
B23: Válvula de corte de artefacto | C23: und | F23: =E23*D23 | K23: 240 | L23: 33 | M23: =L23*K23 | N23: 240 | O23: 35 | P23: =O23*N23 | Q23: =O23*(1-$Q$9) | R23: =Q23*N23
B24: Prueba de hermeticidad departamentos | C24: und | F24: =E24*D24 | K24: 120 | L24: 45 | M24: =L24*K24 | N24: 120 | O24: 45 | P24: =O24*N24 | Q24: =O24*(1-$Q$9) | R24: =Q24*N24
B25: CENTRO DE MEDICIÓN Y GABINETES | C25: glb | F25: =SUM(F27:F28) | J25: =SUM(J27:J28) | M25: =SUM(M27:M28) | P25: =SUM(P27:P28) | R25: =SUM(R27:R28)
B27: Suministro e instalación de gabinetes | C27: und | F27: =E27*D27 | H27: No especifica gabinetes ni meter conector (verificar alcance). | K27: 2 | L27: 160 | M27: =L27*K27 | N27: 3 | O27: 180 | P27: =O27*N27 | Q27: =O27*(1-$Q$9) | R27: =Q27*N27
B28: Meter conector para gabinetes | C28: und | F28: =E28*D28 | K28: 120 | L28: 17 | M28: =L28*K28 | N28: Incluido en su partida de gabinetes (según su texto).
D32: PARCIAL (SIN IGV) | F32: =F9 | J32: =J9 | M32: =M9 | R32: =R9
D33: GASTOS GENERALES | F33: 0 | J33: 0 | M33: 0 | R33: 0
D34: UTILIDADES | F34: 0 | J34: 0 | M34: 0 | R34: 0
D35: SUBTOTAL (SIN IGV) | F35: =SUM(F32:F34) | J35: =SUM(J32:J34) | M35: =SUM(M32:M34) | R35: =SUM(R32:R34)
D36: IGV (18%) | F36: =+F35*0.18 | J36: =+J35*0.18 | M36: =+M35*0.18 | R36: =+R35*0.18
D37: TOTAL INC. IGV | F37: =+F35+F36 | J37: =+J35+J36 | M37: =+M35+M36 | R37: =+R35+R36
B39: DELTA | H39: =IF($F$37=0,"Ingresar meta",$F$37-J37) | K39: =IF($F$37=0,"Ingresar meta",$F$37-M37) | N39: =IF($F$37=0,"Ingresar meta",$F$37-R37)
B40: VARIACIÓN vs. OFERTA MÁS BAJA | H40: =J37/MIN($J$37,$M$37,$R$37)-1 | K40: =M37/MIN($J$37,$M$37,$R$37)-1 | N40: =R37/MIN($J$37,$M$37,$R$37)-1
B41: COSTO POR DEPARTAMENTO (S/, SIN IGV) | H41: =J35/120 | K41: =M35/120 | N41: =R35/120
B42: COSTO POR PUNTO DE CONSUMO (S/, SIN IGV) | H42: =J35/360 | K42: =M35/360 | N42: =R35/360
F43: ADELANTO / TIPO DE GARANTIA | H43: No indica adelanto | K43: Adelanto 0% | N43: Adelanto 30% contra carta fianza
F44: FRECUENCIA DE VALORIZACIONES | H44: Valorizaciones quincenales | K44: Quincenal; pago a 15 días | N44: Mensual; pago a 7 días
F45: FONDO DE GARANTIA | H45: 5% devuelto a los 12 meses | K45: 5% devuelto a los 18 meses | N45: No acepta fondo de garantía
F46: CONTACTO MANO DE OBRA | H46: Empresa: POSTOR A S.A.C. Contacto: (nombre) Correo: ventas@postor-a.example | K46: Empresa: POSTOR B S.A.C. Contacto: (nombre) Correo: costos@postor-b.example | N46: Empresa: POSTOR C S.A.C. Contacto: (nombre) Correo: propuestas@postor-c.example
F47: CONSIDERACIONES: | H47: - Precio global por departamento y por montante, sin desagregar. - No incluye rejillas de ventilación ni obra civil. | K47: - Presupuesto con metrados y P.U. desagregados. - Incluye gabinetes y pintura de tubería de cobre. - No incluye rejillas de ventilación ni arena y cemento. | N47: - Metrado de PE-AL-PE 2025 15% mayor que la base. - Cotiza válvula de corte general de montante (no está en la base). - No incluye pintura de tubería de cobre.
F48: N° DE OBRAS ACTUALES EN EJECUCION | H48: No indica | K48: Por confirmar | N48: 4 obras en ejecución (según carta)
F49: VALIDEZ DE LA OFERTA | H49: 10 días: vence pronto, confirmar vigencia | K49: No indica | N49: 30 días
F50: PLAZO DE EJECUCION | H50: Según avance de obra | K50: Según cronograma de obra | N50: No indica
F51: GARANTIA DE LA INSTALACION | H51: 2 años | K51: 3 años | N51: 3 años

Sheet CC_GAS_PROYX
B2: OBRA: EDIFICIO MULTIFAMILIAR EJEMPLO - TORRE 1
B3: COMPARATIVO - SISTEMA DE INSTALACIONES DE GAS
B4: FECHA: 26 DE OCTUBRE DEL 2026
B6: PRESUPUESTO META | H6: POSTOR A S.A.C. | K6: POSTOR B S.A.C. | N6: POSTOR C S.A.C. | T6: OBSERVACIONES / MOTIVO DEL RESALTADO
B7: Descripción | C7: Unid | D7: Metrado | E7: P.Unitario (S/) | F7: P.Parcial (S/) | H7: Cant. | I7: P.Unitario (S/) | J7: P.Parcial (S/) | K7: Cant. | L7: P.Unitario (S/) | M7: P.Parcial (S/) | N7: Cant. | O7: P.Unitario (S/) | P7: P.Parcial (S/) | Q7: P.Unitario (S/) INC DSCTO 5.00% | R7: P.Parcial (S/) INC DSCTO 5.00%
B9: INSTALACIONES DE GAS | F9: =SUM(F11,F18,F25) | J9: =SUM(J11,J18,J25) | M9: =SUM(M11,M18,M25) | P9: =SUM(P11,P18,P25) | Q9: 0.05 | R9: =SUM(R11,R18,R25)
B11: INSTALACION EN LA RED MONTANTE | F11: =SUM(F12:F17) | J11: =SUM(J12:J17) | M11: =SUM(M12:M17) | P11: =SUM(P12:P17) | R11: =SUM(R12:R17)
B12: INSTALACION EN LA RED MONTANTE - PRECIO GLOBAL POSTOR A | C12: glb | F12: =PRODUCT(D12,E12) | H12: 1 | I12: 18000 | J12: =I12*H12 | T12: GRIS: Partida GLOBAL de Postor A. Precio global de la montante (1 glb x S/ 18,000.00): incluye tubería de cobre, válvulas y prueba de hermeticidad, sin desagregar. Comparar por SUBTOTAL del capítulo.
B13: Tubería Cu tipo L 3/4" vertical en ducto técnico | C13: m | F13: =PRODUCT(D13,E13) | K13: ='POSTOR B'!E7 | L13: =IFERROR(('POSTOR B'!G7)/K13,0) | M13: =K13*L13 | N13: ='POSTOR C'!E6 | O13: =IFERROR(('POSTOR C'!G6)/N13,0) | P13: =N13*O13 | Q13: =O13*(1-$Q$9) | R13: =Q13*N13 | T13: Postor A no la detalla: incluida en su precio global del capítulo. AZUL (cant. Postor C): metrado 25.00 vs base 30.00 (-17%).
B14: Tubería Cu tipo L 1" vertical en ducto técnico | C14: m | F14: =PRODUCT(D14,E14) | K14: ='POSTOR B'!E8 | L14: =IFERROR(('POSTOR B'!G8)/K14,0) | M14: =K14*L14 | N14: ='POSTOR C'!E7 | O14: =IFERROR(('POSTOR C'!G7)/N14,0) | P14: =N14*O14 | Q14: =O14*(1-$Q$9) | R14: =Q14*N14 | T14: Postor A no la detalla: incluida en su precio global del capítulo.
B15: Válvula de corte general de montante | C15: und | F15: =PRODUCT(D15,E15) | N15: ='POSTOR C'!E8 | O15: =IFERROR(('POSTOR C'!G8)/N15,0) | P15: =N15*O15 | Q15: =O15*(1-$Q$9) | R15: =Q15*N15 | T15: ROJO/DORADO: partida cotizada SOLO por Postor C (fuera de la base). Confirmar si se requiere. Postor A no la detalla: incluida en su precio global del capítulo.
B16: Pintura para tubería Cu en ducto técnico | C16: glb | F16: =PRODUCT(D16,E16) | K16: ='POSTOR B'!E9 | L16: =IFERROR(('POSTOR B'!G9)/K16,0) | M16: =K16*L16 | T16: CELESTE: partida no cotizada por Postor C (se valoriza en la NIVELACIÓN). Postor A no la detalla: incluida en su precio global del capítulo.
B17: Prueba de hermeticidad de línea montante | C17: glb | F17: =PRODUCT(D17,E17) | K17: ='POSTOR B'!E10 | L17: =IFERROR(('POSTOR B'!G10)/K17,0) | M17: =K17*L17 | N17: ='POSTOR C'!E9 | O17: =IFERROR(('POSTOR C'!G9)/N17,0) | P17: =N17*O17 | Q17: =O17*(1-$Q$9) | R17: =Q17*N17 | T17: Postor A no la detalla: incluida en su precio global del capítulo.
B18: INSTALACION DE LAS REDES INTERNAS | F18: =SUM(F19:F24) | J18: =SUM(J19:J24) | M18: =SUM(M19:M24) | P18: =SUM(P19:P24) | R18: =SUM(R19:R24)
B19: INSTALACION DE LAS REDES INTERNAS - PRECIO GLOBAL POSTOR A | C19: dpto | F19: =PRODUCT(D19,E19) | H19: 120 | I19: 900 | J19: =I19*H19 | T19: GRIS: Partida GLOBAL de Postor A. Precio global por departamento (120 und x S/ 900.00): incluye tuberías PE-AL-PE, salidas, válvulas y pruebas, sin desagregar. Comparar por SUBTOTAL del capítulo.
B20: Tubería PE-AL-PE 2025 empotrada en losa y muro | C20: m | F20: =PRODUCT(D20,E20) | K20: ='POSTOR B'!E12 | L20: =IFERROR(('POSTOR B'!G12)/K20,0) | M20: =K20*L20 | N20: ='POSTOR C'!E10 | O20: =IFERROR(('POSTOR C'!G10)/N20,0) | P20: =N20*O20 | Q20: =O20*(1-$Q$9) | R20: =Q20*N20 | T20: AMARILLO CLARO: ALTO IMPACTO, diferencia de S/ 12,440 entre Postor B y Postor C. Postor A no la detalla: incluida en su precio global del capítulo. AZUL (cant. Postor C): metrado 2,300.00 vs base 2,000.00 (+15%).
B21: Tubería PE-AL-PE 1216 empotrada en losa y muro | C21: m | F21: =PRODUCT(D21,E21) | K21: ='POSTOR B'!E13 | L21: =IFERROR(('POSTOR B'!G13)/K21,0) | M21: =K21*L21 | N21: ='POSTOR C'!E11 | O21: =IFERROR(('POSTOR C'!G11)/N21,0) | P21: =N21*O21 | Q21: =O21*(1-$Q$9) | R21: =Q21*N21 | T21: Postor A no la detalla: incluida en su precio global del capítulo.
B22: Salidas para terma, cocina y horno | C22: pto | F22: =PRODUCT(D22,E22) | K22: ='POSTOR B'!E14 | L22: =IFERROR(('POSTOR B'!G14)/K22,0) | M22: =K22*L22 | N22: ='POSTOR C'!E12 | O22: =IFERROR(('POSTOR C'!G12)/N22,0) | P22: =N22*O22 | Q22: =O22*(1-$Q$9) | R22: =Q22*N22 | T22: Postor A no la detalla: incluida en su precio global del capítulo.
B23: Válvula de corte de artefacto | C23: und | F23: =PRODUCT(D23,E23) | K23: ='POSTOR B'!E15 | L23: =IFERROR(('POSTOR B'!G15)/K23,0) | M23: =K23*L23 | N23: ='POSTOR C'!E13 | O23: =IFERROR(('POSTOR C'!G13)/N23,0) | P23: =N23*O23 | Q23: =O23*(1-$Q$9) | R23: =Q23*N23 | T23: Postor A no la detalla: incluida en su precio global del capítulo.
B24: Prueba de hermeticidad departamentos | C24: und | F24: =PRODUCT(D24,E24) | K24: ='POSTOR B'!E16 | L24: =IFERROR(('POSTOR B'!G16)/K24,0) | M24: =K24*L24 | N24: ='POSTOR C'!E14 | O24: =IFERROR(('POSTOR C'!G14)/N24,0) | P24: =N24*O24 | Q24: =O24*(1-$Q$9) | R24: =Q24*N24 | T24: Postor A no la detalla: incluida en su precio global del capítulo.
B25: CENTRO DE MEDICIÓN Y GABINETES | F25: =SUM(F26:F27) | J25: =SUM(J26:J27) | M25: =SUM(M26:M27) | P25: =SUM(P26:P27) | R25: =SUM(R26:R27)
B26: Suministro e instalación de gabinetes | C26: und | F26: =PRODUCT(D26,E26) | K26: ='POSTOR B'!E18 | L26: =IFERROR(('POSTOR B'!G18)/K26,0) | M26: =K26*L26 | N26: ='POSTOR C'!E15 | O26: =IFERROR(('POSTOR C'!G15)/N26,0) | P26: =N26*O26 | Q26: =O26*(1-$Q$9) | R26: =Q26*N26 | T26: CELESTE: partida no cotizada por Postor A (se valoriza en la NIVELACIÓN). AZUL (cant. Postor C): metrado 3.00 vs base 2.00 (+50%).
B27: Meter conector para gabinetes | C27: und | F27: =PRODUCT(D27,E27) | K27: ='POSTOR B'!E19 | L27: =IFERROR(('POSTOR B'!G19)/K27,0) | M27: =K27*L27 | N27: INCL. | T27: CELESTE: partida no cotizada por Postor A (se valoriza en la NIVELACIÓN). Postor C: Incluido en su partida de gabinetes (según su texto).
B30: COSTO DIRECTO (SIN IGV) | F30: =F9 | J30: =J9 | M30: =M9 | R30: =R9
B31: GASTOS GENERALES | F31: 0 | I31: 0 | J31: =I31*J30 | L31: 0 | M31: =L31*M30 | Q31: 0 | R31: =Q31*R30 | T31: GG + utilidad por postor (números azules editables): Postor A 0% + 0% · Postor B 0% + 0% · Postor C 0% + 0%.
B32: UTILIDAD | F32: 0 | I32: 0 | J32: =I32*J30 | L32: 0 | M32: =L32*M30 | Q32: 0 | R32: =Q32*R30
B33: SUBTOTAL (SIN IGV) | F33: =SUM(F30:F32) | J33: =SUM(J30:J32) | M33: =SUM(M30:M32) | R33: =SUM(R30:R32) | T33: Debe cuadrar con cada cotización (sin IGV): Postor A S/ 126,000.00 · Postor B S/ 122,000.00 · Postor C S/ 131,917.00.
B34: IGV (18%) | F34: =F33*0.18 | J34: =J33*0.18 | M34: =M33*0.18 | R34: =R33*0.18
B35: TOTAL INC. IGV | F35: =F33+F34 | J35: =J33+J34 | M35: =M33+M34 | R35: =R33+R34
B37: DELTA (PRESUPUESTO META - POSTOR, INC. IGV) | H37: =IF($F$35=0,"Falta ppto. meta",$F$35-J35) | K37: =IF($F$35=0,"Falta ppto. meta",$F$35-M35) | N37: =IF($F$35=0,"Falta ppto. meta",$F$35-R35)
B38: DIFERENCIA vs. MENOR OFERTA (INC. IGV) | H38: =J35-MIN($J$35,$M$35,$R$35) | K38: =M35-MIN($J$35,$M$35,$R$35) | N38: =R35-MIN($J$35,$M$35,$R$35)
B39: VARIACIÓN % vs. MENOR OFERTA | H39: =J35/MIN($J$35,$M$35,$R$35)-1 | K39: =M35/MIN($J$35,$M$35,$R$35)-1 | N39: =R35/MIN($J$35,$M$35,$R$35)-1
B41: ANÁLISIS DE PRECIOS UNITARIOS Y RATIOS (SIN IGV) | H41: Postor A | K41: Postor B | N41: Postor C
B42: COSTO POR DEPARTAMENTO (S/, SIN IGV) | H42: =J33/120 | K42: =M33/120 | N42: =R33/120
B43: COSTO POR PUNTO DE CONSUMO (S/, SIN IGV) | H43: =J33/360 | K43: =M33/360 | N43: =R33/360
B44: Capítulo INSTALACION EN LA RED MONTANTE (S/, sin IGV) | H44: =J11 | K44: =M11 | N44: =R11
B45: Capítulo INSTALACION DE LAS REDES INTERNAS (S/, sin IGV) | H45: =J18 | K45: =M18 | N45: =R18
B46: Capítulo CENTRO DE MEDICIÓN Y GABINETES (S/, sin IGV) | H46: =J25 | K46: =M25 | N46: =R25
B48: NIVELACIÓN POR ALCANCE (SIN IGV) | H48: Postor A | K48: Postor B | N48: Postor C
B49: (+) Partidas no cotizadas (celestes y rojo/dorado), al menor precio de los otros postores | H49: =MIN(M26,R26)+M27 | K49: =R15 | N49: =M16 | T49: Escenario conservador: a cada postor se le suman las partidas que no cotiza ni declara incluidas, al menor precio neto de los demás postores.
...

Sheet LEYENDA Y NOTAS
B2: LEYENDA Y NOTAS - COMPARATIVO - SISTEMA DE INSTALACIONES DE GAS
B3: Estándar de colores del cuadro comparativo. Cada fila resaltada de la Hoja 2 explica su motivo en OBSERVACIONES.
B5: 1. CÓDIGO DE COLORES
B6: Formato (muestra) | C6: Dónde se aplica | F6: Qué significa / qué hacer
B7: Azul marino, letra blanca | C7: Columnas D-F, títulos de bloque | F7: Presupuesto meta (referencia). Si está vacío, falta el ppto. meta.
B8: Verde intenso, letra blanca | C8: Encabezado de postor (Hoja 2) | F8: Postor recomendado (mejor relación precio / alcance / control).
B9: Verde limón | C9: Encabezado de postor / DELTA | F9: Menor precio ofertado o bajo meta.
B10: Amarillo | C10: Encabezado de postor (Hoja 2) | F10: Postor en negociación u observado.
B11: Naranja, letra roja | C11: Encabezado de postor (Hoja 2) | F11: Oferta más cara / sobre meta.
B12: Negro, letra amarilla | C12: Encabezado de postor | F12: Versión anterior de una oferta.
B13: Gris, negrita | C13: Descripción | F13: Precio global que cubre varias partidas: comparar por subtotal del capítulo.
B14: Descripción roja sobre dorado claro | C14: Descripción | F14: Partida fuera de la base cotizada por UN solo postor. Decidir si se necesita.
B15: Descripción azul sobre dorado claro | C15: Descripción | F15: Fuera de la base pero la cotizan VARIOS postores: alcance real no considerado.
B16: Fondo celeste | C16: Descripción | F16: Partida de la base que algún postor no cotiza ni declara incluida. Se valoriza en la NIVELACIÓN.
B17: Fondo amarillo claro | C17: Descripción | F17: Alto impacto: diferencia mayor al umbral entre postores.
... B25: Texto negro negrita (criterios) | C25: Bloque de criterios | F25: Dato faltante o a confirmar con el postor.
B27: 2. RESULTADO (vinculado al cuadro desglosado)
B28: Concepto | C28: Postor A | D28: Postor B | E28: Postor C
B29: Precio ofertado sin IGV | C29: ='CC_GAS_PROYX'!J33 | D29: ='CC_GAS_PROYX'!M33 | E29: ='CC_GAS_PROYX'!R33
B30: Precio nivelado por alcance sin IGV | C30: ='CC_GAS_PROYX'!H50 | D30: ='CC_GAS_PROYX'!K50 | E30: ='CC_GAS_PROYX'!N50
B31: Variación % nivelada vs. menor | C31: ='CC_GAS_PROYX'!H52 | D31: ='CC_GAS_PROYX'!K52 | E31: ='CC_GAS_PROYX'!N52
B33: 3. CONCLUSIONES DEL INGENIERO DE COSTOS
B34: • Postor B es la menor oferta (S/ 122,000 sin IGV) y la única con metrado completo: es la base de homologación.
B35: • Postor A queda 3.3% arriba y cotiza en globales: no permite controlar valorizaciones ni adicionales.
B36: • Postor C es el más caro aun con 5% de descuento y pide 30% de adelanto sin fondo de garantía.

Sheet POSTOR A
B1: POSTOR A S.A.C. - COTIZACIÓN N° 001-2026 (transcrita del PDF)
B2: RUC | C2: Por confirmar
B3: Fecha | C3: 10/10/2026
B5: Ítem | C5: Descripción | D5: Und | E5: Metrado | F5: P.U. (S/) | G5: Parcial (S/) | H5: Control E×F-G
B6: 1.0 | C6: Red montante (global) | D6: glb | E6: 1 | F6: 18000 | G6: =E6*F6 | H6: =E6*F6-G6
B7: 2.0 | C7: Redes internas por departamento (global) | D7: dpto | E7: 120 | F7: 900 | G7: =E7*F7 | H7: =E7*F7-G7
C8: SUBTOTAL (suma de partidas) | G8: =SUM(G6:G7)
C9: TOTAL DECLARADO SIN IGV | G9: 126000
C10: DIFERENCIA (declarado - suma) | G10: =G9-G8
C12: * No incluye rejillas de ventilación.
C13: * Validez: 10 días.

Sheet POSTOR B
B1: POSTOR B S.A.C. - PRESUPUESTO REV. 01 (transcrito)
B2: RUC | C2: 20000000001
B3: Fecha | C3: 15/10/2026
B5: Ítem | C5: Descripción | D5: Und | E5: Metrado | F5: P.U. (S/) | G5: Parcial (S/) | H5: Control E×F-G
B6: 1 | C6: RED MONTANTE
B7: 1.01 | C7: Tubería Cu tipo L 3/4" | D7: m | E7: 30 | F7: 90 | G7: =E7*F7 | H7: =E7*F7-G7
B8: 1.02 | C8: Tubería Cu tipo L 1" | D8: m | E8: 40 | F8: 105 | G8: =E8*F8 | H8: =E8*F8-G8
B9: 1.03 | C9: Pintura de tubería Cu | D9: glb | E9: 1 | F9: 600 | G9: =E9*F9 | H9: =E9*F9-G9
B10: 1.04 | C10: Prueba de hermeticidad de montante | D10: glb | E10: 1 | F10: 500 | G10: =E10*F10 | H10: =E10*F10-G10
B11: 2 | C11: REDES INTERNAS
B12: 2.01 | C12: Tubería PE-AL-PE 2025 | D12: m | E12: 2000 | F12: 20 | G12: =E12*F12 | H12: =E12*F12-G12
B13: 2.02 | C13: Tubería PE-AL-PE 1216 | D13: m | E13: 2600 | F13: 18 | G13: =E13*F13 | H13: =E13*F13-G13
B14: 2.03 | C14: Salidas para terma, cocina y horno | D14: pto | E14: 360 | F14: 32 | G14: =E14*F14 | H14: =E14*F14-G14
B15: 2.04 | C15: Válvula de corte de artefacto | D15: und | E15: 240 | F15: 33 | G15: =E15*F15 | H15: =E15*F15-G15
B16: 2.05 | C16: Prueba de hermeticidad de departamentos | D16: und | E16: 120 | F16: 45 | G16: =E16*F16 | H16: =E16*F16-G16
B17: 3 | C17: CENTRO DE MEDICIÓN
B18: 3.01 | C18: Gabinetes | D18: und | E18: 2 | F18: 160 | G18: =E18*F18 | H18: =E18*F18-G18
B19: 3.02 | C19: Meter conector | D19: und | E19: 120 | F19: 17 | G19: =E19*F19 | H19: =E19*F19-G19
C20: SUBTOTAL (suma de partidas) | G20: =SUM(G6:G19)
C21: TOTAL DECLARADO SIN IGV | G21: 122000
C22: DIFERENCIA (declarado - suma) | G22: =G21-G20
C24: * Garantía 3 años.
C25: * Adelanto 0%; fondo de garantía 5% a 18 meses.

Sheet POSTOR C
B1: POSTOR C S.A.C. - PROPUESTA (transcrita del PDF)
B2: RUC | C2: 20000000002
B3: Fecha | C3: 12/10/2026
B5: Ítem | C5: Descripción | D5: Und | E5: Metrado | F5: P.U. (S/) | G5: Parcial (S/) | H5: Control E×F-G
B6: 01.01 | C6: Tubería cobre 3/4" | D6: m | E6: 25 | F6: 110 | G6: =E6*F6 | H6: =E6*F6-G6
B7: 01.02 | C7: Tubería cobre 1" | D7: m | E7: 40 | F7: 140 | G7: =E7*F7 | H7: =E7*F7-G7
B8: 01.03 | C8: Válvula de corte general de montante | D8: und | E8: 1 | F8: 120 | G8: =E8*F8 | H8: =E8*F8-G8
B9: 01.04 | C9: Prueba de hermeticidad | D9: glb | E9: 1 | F9: 650 | G9: =E9*F9 | H9: =E9*F9-G9
B10: 02.01 | C10: Tubería PE-AL-PE 2025 | D10: m | E10: 2300 | F10: 24 | G10: =E10*F10 | H10: =E10*F10-G10
B11: 02.02 | C11: Tubería PE-AL-PE 1216 | D11: m | E11: 2600 | F11: 19 | G11: =E11*F11 | H11: =E11*F11-G11
B12: 02.03 | C12: Salidas | D12: pto | E12: 360 | F12: 30 | G12: =E12*F12 | H12: =E12*F12-G12
B13: 02.04 | C13: Válvula de artefacto | D13: und | E13: 240 | F13: 35 | G13: =E13*F13 | H13: =E13*F13-G13
B14: 02.05 | C14: Prueba de hermeticidad por dpto | D14: und | E14: 120 | F14: 45 | G14: =E14*F14 | H14: =E14*F14-G14
B15: 03.01 | C15: Gabinetes | D15: und | E15: 3 | F15: 180 | G15: =E15*F15 | H15: =E15*F15-G15
C16: SUBTOTAL (suma de partidas) | G16: =SUM(G6:G15)
C17: TOTAL DECLARADO SIN IGV | G17: 131917
C18: DIFERENCIA (declarado - suma) | G18: =G17-G16
C20: * Descuento 5% sobre el total: S/ 138,860.00 - 5% = S/ 131,917.00 + IGV.
