Workbook

Sheet M4-E3
A1: OBRA | C1: FECHA | D1: =+TODAY() -> 46318 | E1: FORMATO:CONTROL DE PLAN DE PROCURA DE OBRAS | K1: Codigo: 2026-09-PROCURA | N1: Versión:00 | P1: Fecha: | Q1: 16-09-26
A2: SUBCONTRATAS/PROVEEDORES/MATERIALES | B2: T. envío de info a Costos Obra | C2: Fecha de Envío info a Costos Obra Responsable:Proveedor / Subcontratista | D2: STATUS | E2: Tiempo elaboración cuadro comparativo (d) | F2: Fecha de envío de cuadro comparativo. Responsable: OBRA COSTOS | G2: STATUS | H2: Tiempo de negociación y aprobación de gerencia (d) | I2: Fecha de Selección de Subcontrata y/o proveedor | J2: STATUS | K2: SUBCONTRATA O PROVEEDOR SELECCIONADO | L2: Tiempo de generación de OS/OC (d) | M2: Fecha de firma de contrato | N2: STATUS | O2: Tiempo de preparación de inicio y/o importación (d) | P2: HITO DE LA OBRA | Q2: Inicio de ejecución
A3: SC Vigilancia de obra | B3: 15 | C3: =+F3-E3-B3 -> 46241 | D3: Cerrado | E3: 15 | F3: =+I3-H3 -> 46271 | G3: Cerrado | H3: 7 | I3: =+M3-L3 -> 46278 | J3: Cerrado | K3: ORELIA GROUP SOUTH AMERICAN SECURITY S.A.C. | L3: 7 | M3: =+Q3-O3 -> 46285 | N3: Cerrado | O3: 15 | P3: INICIO DE OBRA | Q3: 46300
A4: SC de Demolición | B4: 15 | C4: =+F4-E4-B4 -> 46213 | D4: Cerrado | E4: 15 | F4: =+I4-H4 -> 46243 | G4: Cerrado | H4: 7 | I4: =+M4-L4 -> 46250 | J4: Cerrado | K4: MAQUIJAL INGENIEROS S.A.C. | L4: 7 | M4: =+Q4-O4 -> 46257 | N4: Cerrado | O4: 15 | P4: INICIO DE OBRA | Q4: =VLOOKUP($A$1&"xx"&P4,HITOS!D:E,2,FALSE) -> 46272
A5: SC de Excavación y eliminación | B5: 15 | C5: =+F5-B5 -> 46228 | D5: Cerrado | E5: 15 | F5: =+I5-H5 -> 46243 | G5: Cerrado | H5: 7 | I5: =+M5-L5 -> 46250 | J5: Cerrado | K5: MAQUIJAL INGENIEROS S.A.C. | L5: 7 | M5: =+Q5-O5 -> 46257 | N5: Cerrado | O5: 15 | P5: INICIO DE OBRA | Q5: =VLOOKUP($A$1&"xx"&P5,HITOS!D:E,2,FALSE) -> 46272
A6: SC PILOTO 4.3 | C6: =+F6-B6 -> 46250 | D6: Cerrado | E6: 15 | F6: =+I6-H6 -> 46250 | G6: Cerrado | H6: 7 | I6: =+M6-L6 -> 46257 | J6: Cerrado | M6: =+Q6-O6 -> 46257 | N6: Cerrado | O6: 15 | P6: INICIO DE OBRA | Q6: =VLOOKUP($A$1&"xx"&P6,HITOS!D:E,2,FALSE) -> 46272
A7: SC Anclajes | B7: 15 | C7: =+F7-E7-B7 -> 46213 | D7: Cerrado | E7: 15 | F7: =+I7-H7 -> 46243 | G7: Cerrado | H7: 7 | I7: =+M7-L7 -> 46250 | J7: Cerrado | K7: BATALLA DE JUNIN | L7: 7 | M7: =+Q7-O7 -> 46257 | N7: Cerrado | O7: 15 | P7: INICIO DE OBRA | Q7: =VLOOKUP($A$1&"xx"&P7,HITOS!D:E,2,FALSE) -> 46272
A8: SC de Arriendo de Encofrado Modular (Muros Anclados) | B8: 15 | C8: =+F8-B8 -> 46228 | D8: Cerrado | E8: 15 | F8: =+I8-H8 -> 46243 | G8: Cerrado | H8: 7 | I8: =+M8-L8 -> 46250 | J8: Cerrado | K8: UNISPAN | L8: 7 | M8: =+Q8-O8 -> 46257 | N8: Cerrado | O8: 15 | P8: INICIO DE OBRA | Q8: =VLOOKUP($A$1&"xx"&P8,HITOS!D:E,2,FALSE) -> 46272
A9: SUMINISTRO de Acero | B9: 15 | C9: =+F9-B9 -> 46228 | D9: Cerrado | E9: 15 | F9: =+I9-H9 -> 46243 | G9: Cerrado | H9: 7 | I9: =+M9-L9 -> 46250 | J9: Cerrado | K9: INAKFERRO | L9: 7 | M9: =+Q9-O9 -> 46257 | N9: Cerrado | O9: 15 | P9: INICIO DE OBRA | Q9: =VLOOKUP($A$1&"xx"&P9,HITOS!D:E,2,FALSE) -> 46272
A10: SC de Torre Grua | B10: 15 | C10: =+F10-B10 -> 46228 | D10: Cerrado | E10: 15 | F10: =+I10-H10 -> 46243 | G10: Cerrado | H10: 7 | I10: =+M10-L10 -> 46250 | J10: Cerrado | K10: JM IZAJES Y TECNOLOGIA | L10: 7 | M10: =+Q10-O10 -> 46257 | N10: Cerrado | O10: 15 | P10: INICIO DE OBRA | Q10: =VLOOKUP($A$1&"xx"&P10,HITOS!D:E,2,FALSE) -> 46272
A11: SC de MO de Instalaciones Electricas | B11: 15 | C11: =+F11-B11 -> 46228 | D11: Cerrado | E11: 15 | F11: =+I11-H11 -> 46243 | G11: Cerrado | H11: 7 | I11: =+M11-L11 -> 46250 | J11: Cerrado | K11: DYJ | L11: 7 | M11: =+Q11-O11 -> 46257 | N11: Cerrado | O11: 15 | P11: INICIO DE OBRA | Q11: =VLOOKUP($A$1&"xx"&P11,HITOS!D:E,2,FALSE) -> 46272
A12: SC de MO de Instalaciones Sanitarias | B12: 15 | C12: =+F12-B12 -> 46228 | D12: Cerrado | E12: 15 | F12: =+I12-H12 -> 46243 | G12: Cerrado | H12: 7 | I12: =+M12-L12 -> 46250 | J12: Cerrado | K12: JM GERENCIA | L12: 7 | M12: =+Q12-O12 -> 46257 | N12: Cerrado | O12: 15 | P12: INICIO DE OBRA | Q12: =VLOOKUP($A$1&"xx"&P12,HITOS!D:E,2,FALSE) -> 46272
A13: Concreto premezclado | B13: 15 | C13: =+F13-B13 -> 46228 | D13: Pendiente | E13: 15 | F13: =+I13-H13 -> 46243 | G13: Pendiente | H13: 7 | I13: =+M13-L13 -> 46250 | J13: Pendiente | K13: UNACEM | L13: 7 | M13: =+Q13-O13 -> 46257 | N13: Pendiente | O13: 15 | P13: INICIO DE OBRA | Q13: =VLOOKUP($A$1&"xx"&P13,HITOS!D:E,2,FALSE) -> 46272
A14: Asensores (importación) | B14: 15 | C14: =+F14-B14 -> 46228 | D14: Pendiente | E14: 15 | F14: =+I14-H14 -> 46243 | G14: Pendiente | H14: 7 | I14: =+M14-L14 -> 46250 | J14: Pendiente | L14: 7 | M14: =+Q14-O14 -> 46257 | N14: Pendiente | O14: 15 | P14: INICIO DE OBRA | Q14: =VLOOKUP($A$1&"xx"&P14,HITOS!D:E,2,FALSE) -> 46272
A15: SC de ACI a todo costo | B15: 15 | C15: =+F15-B15 -> 46408 | D15: Pendiente | E15: 15 | F15: =+I15-H15 -> 46423 | G15: Pendiente | H15: 7 | I15: =+M15-L15 -> 46430 | J15: Pendiente | L15: 7 | M15: =+Q15-O15 -> 46437 | N15: Pendiente | O15: 15 | P15: =+HITOS!$B$19 -> FIN DE TORRE | Q15: =VLOOKUP($A$1&"xx"&P15,HITOS!D:E,2,FALSE) -> 46452
A16: SC de Arriendo de Encofrado Modular (Casco) | B16: 15 | C16: =+F16-B16 -> 46408 | D16: Pendiente | E16: 15 | F16: =+I16-H16 -> 46423 | G16: Pendiente | H16: 7 | I16: =+M16-L16 -> 46430 | J16: Pendiente | K16: UNISPAN | L16: 7 | M16: =+Q16-O16 -> 46437 | N16: Pendiente | O16: 15 | P16: =+HITOS!$B$19 -> FIN DE TORRE | Q16: =VLOOKUP($A$1&"xx"&P16,HITOS!D:E,2,FALSE) -> 46452
A17: SC Tabiquería a todo costo (Contratista 1) | B17: 15 | C17: =+F17-B17 -> 46347 | D17: Pendiente | E17: 15 | F17: =+I17-H17 -> 46362 | G17: Pendiente | H17: 7 | I17: =+M17-L17 -> 46369 | J17: Pendiente | L17: 7 | M17: =+Q17-O17 -> 46376 | N17: Pendiente | O17: 15 | P17: =HITOS!$B$20 -> ACABADOS HUMEDOS EN TORRE | Q17: =VLOOKUP($A$1&"xx"&P17,HITOS!D:E,2,FALSE) -> 46391
A18: SC Tabiquería a todo costo (Contratista 2) | B18: 15 | C18: =+F18-B18 -> 46347 | D18: Pendiente | E18: 15 | F18: =+I18-H18 -> 46362 | G18: Pendiente | H18: 7 | I18: =+M18-L18 -> 46369 | J18: Pendiente | L18: 7 | M18: =+Q18-O18 -> 46376 | N18: Pendiente | O18: 15 | P18: =HITOS!$B$20 -> ACABADOS HUMEDOS EN TORRE | Q18: =VLOOKUP($A$1&"xx"&P18,HITOS!D:E,2,FALSE) -> 46391
A19: SC Instalaciones de GAS a todo costo | B19: 15 | C19: =+F19-B19 -> 46347 | D19: Pendiente | E19: 15 | F19: =+I19-H19 -> 46362 | G19: Pendiente | H19: 7 | I19: =+M19-L19 -> 46369 | J19: Pendiente | L19: 7 | M19: =+Q19-O19 -> 46376 | N19: Pendiente | O19: 15 | P19: =HITOS!$B$20 -> ACABADOS HUMEDOS EN TORRE | Q19: =VLOOKUP($A$1&"xx"&P19,HITOS!D:E,2,FALSE) -> 46391
A20: SC Instalaciones Mecánicas a todo costo | B20: 15 | C20: =+F20-B20 -> 46261 | D20: Pendiente | E20: 15 | F20: =+I20-H20 -> 46276 | G20: Pendiente | H20: 7 | I20: =+M20-L20 -> 46283 | J20: Pendiente | L20: 7 | M20: =+Q20-O20 -> 46290 | N20: Pendiente | O20: 15 | P20: FIN DE MUROS ANCLADOS | Q20: =VLOOKUP($A$1&"xx"&P20,HITOS!D:E,2,FALSE) -> 46305
A21: SC Sistema de Presión Constante a todo costo | B21: 15 | C21: =+F21-B21 -> 46261 | D21: Pendiente | E21: 15 | F21: =+I21-H21 -> 46276 | G21: Pendiente | H21: 7 | I21: =+M21-L21 -> 46283 | J21: Pendiente | L21: 7 | M21: =+Q21-O21 -> 46290 | N21: Pendiente | O21: 15 | P21: FIN DE MUROS ANCLADOS | Q21: =VLOOKUP($A$1&"xx"&P21,HITOS!D:E,2,FALSE) -> 46305
A22: SC Bombas sumergibles para sumideros a todo costo | B22: 15 | C22: =+F22-B22 -> 46261 | D22: Pendiente | E22: 15 | F22: =+I22-H22 -> 46276 | G22: Pendiente | H22: 7 | I22: =+M22-L22 -> 46283 | J22: Pendiente | L22: 7 | M22: =+Q22-O22 -> 46290 | N22: Pendiente | O22: 15 | P22: FIN DE MUROS ANCLADOS | Q22: =VLOOKUP($A$1&"xx"&P22,HITOS!D:E,2,FALSE) -> 46305
A23: SC Bomba ACI y Jockey a todo costo | B23: 15 | C23: =+F23-B23 -> 46261 | D23: Pendiente | E23: 15 | F23: =+I23-H23 -> 46276 | G23: Pendiente | H23: 7 | I23: =+M23-L23 -> 46283 | J23: Pendiente | L23: 7 | M23: =+Q23-O23 -> 46290 | N23: Pendiente | O23: 15 | P23: FIN DE MUROS ANCLADOS | Q23: =VLOOKUP($A$1&"xx"&P23,HITOS!D:E,2,FALSE) -> 46305
A24: SC Ventanas y Mamparas Torre a todo costo (importación) | B24: 15 | C24: =+F24-B24 -> 46327 | D24: Pendiente | E24: 15 | F24: =+I24-H24 -> 46342 | G24: Pendiente | H24: 7 | I24: =+M24-L24 -> 46349 | J24: Pendiente | L24: 7 | M24: =+Q24-O24 -> 46356 | N24: Pendiente | O24: 15 | P24: =HITOS!$B$21 -> ACABADOS SECOS EN TORRE | Q24: =VLOOKUP($A$1&"xx"&P24,HITOS!D:E,2,FALSE) -> 46371
A25: SC Carpintería Metálica DEPARTAMENTOS a todo costo | B25: 15 | C25: =+F25-B25 -> 46327 | D25: Pendiente | E25: 15 | F25: =+I25-H25 -> 46342 | G25: Pendiente | H25: 7 | I25: =+M25-L25 -> 46349 | J25: Pendiente | L25: 7 | M25: =+Q25-O25 -> 46356 | N25: Pendiente | O25: 15 | P25: =HITOS!$B$21 -> ACABADOS SECOS EN TORRE | Q25: =VLOOKUP($A$1&"xx"&P25,HITOS!D:E,2,FALSE) -> 46371
A26: SC Carpintería Metálica SOTANOS a todo costo | B26: 15 | C26: =+F26-B26 -> 46327 | D26: Pendiente | E26: 15 | F26: =+I26-H26 -> 46342 | G26: Pendiente | H26: 7 | I26: =+M26-L26 -> 46349 | J26: Pendiente | L26: 7 | M26: =+Q26-O26 -> 46356 | N26: Pendiente | O26: 15 | P26: =HITOS!$B$21 -> ACABADOS SECOS EN TORRE | Q26: =VLOOKUP($A$1&"xx"&P26,HITOS!D:E,2,FALSE) -> 46371
A27: SC Carpintería Metálica AREAS COMUNES a todo costo | B27: 15 | C27: =+F27-B27 -> 46327 | D27: Pendiente | E27: 15 | F27: =+I27-H27 -> 46342 | G27: Pendiente | H27: 7 | I27: =+M27-L27 -> 46349 | J27: Pendiente | L27: 7 | M27: =+Q27-O27 -> 46356 | N27: Pendiente | O27: 15 | P27: =HITOS!$B$21 -> ACABADOS SECOS EN TORRE | Q27: =VLOOKUP($A$1&"xx"&P27,HITOS!D:E,2,FALSE) -> 46371
A28: SC Mallas Anticaídas a todo costo | B28: 15 | C28: =+F28-B28 -> 46327 | D28: Pendiente | E28: 15 | F28: =+I28-H28 -> 46342 | G28: Pendiente | H28: 7 | I28: =+M28-L28 -> 46349 | J28: Pendiente | L28: 7 | M28: =+Q28-O28 -> 46356 | N28: Pendiente | O28: 15 | P28: =HITOS!$B$21 -> ACABADOS SECOS EN TORRE | Q28: =VLOOKUP($A$1&"xx"&P28,HITOS!D:E,2,FALSE) -> 46371
A29: SC Encapsulado a todo costo | B29: 15 | C29: =+F29-B29 -> 46327 | D29: Pendiente | E29: 15 | F29: =+I29-H29 -> 46342 | G29: Pendiente | H29: 7 | I29: =+M29-L29 -> 46349 | J29: Pendiente | L29: 7 | M29: =+Q29-O29 -> 46356 | N29: Pendiente | O29: 15 | P29: =HITOS!$B$21 -> ACABADOS SECOS EN TORRE | Q29: =VLOOKUP($A$1&"xx"&P29,HITOS!D:E,2,FALSE) -> 46371
A30: SUMINISTRO de Tableros EMPOTRADOS | B30: 15 | C30: =+F30-B30 -> 46327 | D30: Pendiente | E30: 15 | F30: =+I30-H30 -> 46342 | G30: Pendiente | H30: 7 | I30: =+M30-L30 -> 46349 | J30: Pendiente | L30: 7 | M30: =+Q30-O30 -> 46356 | N30: Pendiente | O30: 15 | P30: =HITOS!$B$21 -> ACABADOS SECOS EN TORRE | Q30: =VLOOKUP($A$1&"xx"&P30,HITOS!D:E,2,FALSE) -> 46371
A31: SUMINISTRO DE ENCHAPE mano de obra | B31: 15 | C31: =+F31-B31 -> 46327 | D31: Pendiente | E31: 15 | F31: =+I31-H31 -> 46342 | G31: Pendiente | H31: 7 | I31: =+M31-L31 -> 46349 | J31: Pendiente | L31: 7 | M31: =+Q31-O31 -> 46356 | N31: Pendiente | O31: 15 | P31: =HITOS!$B$21 -> ACABADOS SECOS EN TORRE | Q31: =VLOOKUP($A$1&"xx"&P31,HITOS!D:E,2,FALSE) -> 46371
A32: SC Nivelacion de pisos y contrapisos. | B32: 15 | C32: =+F32-B32 -> 46327 | D32: Pendiente | E32: 15 | F32: =+I32-H32 -> 46342 | G32: Pendiente | H32: 7 | I32: =+M32-L32 -> 46349 | J32: Pendiente | L32: 7 | M32: =+Q32-O32 -> 46356 | N32: Pendiente | O32: 15 | P32: =HITOS!$B$21 -> ACABADOS SECOS EN TORRE | Q32: =VLOOKUP($A$1&"xx"&P32,HITOS!D:E,2,FALSE) -> 46371
A33: SC ENCHAPE mano de obra | B33: 15 | C33: =+F33-B33 -> 46327 | D33: Pendiente | E33: 15 | F33: =+I33-H33 -> 46342 | G33: Pendiente | H33: 7 | I33: =+M33-L33 -> 46349 | J33: Pendiente | L33: 7 | M33: =+Q33-O33 -> 46356 | N33: Pendiente | O33: 15 | P33: =HITOS!$B$21 -> ACABADOS SECOS EN TORRE | Q33: =VLOOKUP($A$1&"xx"&P33,HITOS!D:E,2,FALSE) -> 46371
A34: SC SISTEMA FOTOVOLTAICO a todo costo | B34: 15 | C34: =+F34-B34 -> 46327 | D34: Pendiente | E34: 15 | F34: =+I34-H34 -> 46342 | G34: Pendiente | H34: 7 | I34: =+M34-L34 -> 46349 | J34: Pendiente | L34: 7 | M34: =+Q34-O34 -> 46356 | N34: Pendiente | O34: 15 | P34: =HITOS!$B$21 -> ACABADOS SECOS EN TORRE | Q34: =VLOOKUP($A$1&"xx"&P34,HITOS!D:E,2,FALSE) -> 46371
A35: SC IMPERMEABILIZACION de Cisternas a todo costo | B35: 15 | C35: =+F35-B35 -> 46327 | D35: Pendiente | E35: 15 | F35: =+I35-H35 -> 46342 | G35: Pendiente | H35: 7 | I35: =+M35-L35 -> 46349 | J35: Pendiente | L35: 7 | M35: =+Q35-O35 -> 46356 | N35: Pendiente | O35: 15 | P35: =HITOS!$B$21 -> ACABADOS SECOS EN TORRE | Q35: =VLOOKUP($A$1&"xx"&P35,HITOS!D:E,2,FALSE) -> 46371
... A37: SC PINTURA DE TRÁFICO a todo costo | B37: 15 | C37: =+F37-B37 -> 46327 | D37: Pendiente | E37: 15 | F37: =+I37-H37 -> 46342 | G37: Pendiente | H37: 7 | I37: =+M37-L37 -> 46349 | J37: Pendiente | L37: 7 | M37: =+Q37-O37 -> 46356 | N37: Pendiente | O37: 15 | P37: =HITOS!$B$21 -> ACABADOS SECOS EN TORRE | Q37: =VLOOKUP($A$1&"xx"&P37,HITOS!D:E,2,FALSE) -> 46371
A38: SC Sellos Cortafuego a todo costo | B38: 15 | C38: =+F38-B38 -> 46711 | D38: Pendiente | E38: 15 | F38: =+I38-H38 -> 46726 | G38: Pendiente | H38: 7 | I38: =+M38-L38 -> 46733 | J38: Pendiente | L38: 7 | M38: =+Q38-O38 -> 46740 | N38: Pendiente | O38: 15 | P38: =HITOS!$B$22 -> ENTREGA DE DPTOS TORRE 3 | Q38: =VLOOKUP($A$1&"xx"&P38,HITOS!D:E,2,FALSE) -> 46755
A39: SC LIMPIEZA Y DESINFECCION de Cisternas | B39: 15 | C39: =+F39-B39 -> 46711 | D39: Pendiente | E39: 15 | F39: =+I39-H39 -> 46726 | G39: Pendiente | H39: 7 | I39: =+M39-L39 -> 46733 | J39: Pendiente | L39: 7 | M39: =+Q39-O39 -> 46740 | N39: Pendiente | O39: 15 | P39: =HITOS!$B$22 -> ENTREGA DE DPTOS TORRE 3 | Q39: =VLOOKUP($A$1&"xx"&P39,HITOS!D:E,2,FALSE) -> 46755
A40: SUMINISTRO de Tableros ADOSADOS | B40: 15 | C40: =+F40-B40 -> 46711 | D40: Pendiente | E40: 15 | F40: =+I40-H40 -> 46726 | G40: Pendiente | H40: 7 | I40: =+M40-L40 -> 46733 | J40: Pendiente | L40: 7 | M40: =+Q40-O40 -> 46740 | N40: Pendiente | O40: 15 | P40: =HITOS!$B$22 -> ENTREGA DE DPTOS TORRE 3 | Q40: =VLOOKUP($A$1&"xx"&P40,HITOS!D:E,2,FALSE) -> 46755
A41: SC PINTURA INTERIOR a todo costo | B41: 15 | C41: =+F41-B41 -> 46711 | D41: Pendiente | E41: 15 | F41: =+I41-H41 -> 46726 | G41: Pendiente | H41: 7 | I41: =+M41-L41 -> 46733 | J41: Pendiente | L41: 7 | M41: =+Q41-O41 -> 46740 | N41: Pendiente | O41: 15 | P41: =HITOS!$B$22 -> ENTREGA DE DPTOS TORRE 3 | Q41: =VLOOKUP($A$1&"xx"&P41,HITOS!D:E,2,FALSE) -> 46755
...

Sheet Comparo
A2: obra 3 | B2: obra 4 | C2: obra 5 | D2: Mambo 4.3 | E2: Mambo 6.1 | F2: Mambo 5.2 | G2: Mambo 5.2
A3: SC de Demolición | B3: SC de Demolición | C3: SC de Demolición | D3: SC Vigilancia de obra | E3: SC Vigilancia de obra | F3: SC de Demolición (NO ES ALCANCE DE 5.2) | G3: SC de Excavación y eliminación
A4: SC de Excavación y eliminación | B4: SC de Excavación y eliminación | C4: SC de Excavación y eliminación | D4: SC de Demolición | E4: SC de Demolición | F4: SC de Excavación y eliminación | G4: SC de Torre Grua
A5: SC de Topografia | B5: SC de Topografia | C5: SC de Topografia | D5: SC de Excavación y eliminación | E5: SC de Excavación y eliminación | F5: SC de Topografia (LO EJECUTA CASA) | G5: SC de Instalaciones Electricas
A6: SC de Torre Grua | B6: SC de Torre Grua | C6: SC de Torre Grua | D6: SC PILOTO 4.3 | E6: SC PILOTO 6.1 | F6: SC de Torre Grua | G6: SC de Instalaciones Sanitarias
A7: SC de Anclajes | B7: SC de Anclajes | C7: SC de Anclajes | D7: SC de Torre Grua | E7: SC Anclajes | F7: SC de Anclajes (ALCANCE 5.1) | G7: SC de ACI
A8: SC de Acero | B8: SC de Acero | C8: SC de Acero | D8: SC de Anclajes | E8: SC de Arriendo de Encofrado Modular (Muros Anclados) | F8: SC de Acero (LO EJECUTA CASA) | G8: SC de Instalacion de GN
A9: SC de Encofrado | B9: SC de Encofrado | C9: SC de Encofrado | D9: Suministro de Acero | E9: SUMINISTRO de Acero | F9: SC de Encofrado | G9: Acero corrugado
A10: SC de Instalaciones Electricas | B10: SC de Instalaciones Electricas | C10: SC de Instalaciones Electricas | D10: SC de Arriendo de Encofrado Modular | E10: SC de Torre Grua | F10: SC de Instalaciones Electricas | G10: SC de Encofrado
A11: Concreto premezclado | B11: Concreto premezclado | C11: Concreto premezclado | D11: SC de MO de Instalaciones Electricas | E11: SC de MO de Instalaciones Electricas | F11: Concreto premezclado | G11: Concreto premezclado
A12: Acero corrugado | B12: Acero corrugado | C12: Acero corrugado | D12: SC de MO de Instalaciones Sanitarias | E12: SC de MO de Instalaciones Sanitarias | F12: Acero corrugado | G12: Asensores (importación)
A13: Ascensores (importación) | B13: Asensores (importación) | C13: Asensores (importación) | D13: Concreto premezclado | E13: Supervisor de concreto | F13: Asensores (importación) | G13: SC Ascensor(MO)
... A51: SC Puertas Ducto Montantes | B51: SC Ventanas y Mamparas Torre (Importación) | C51: SC Mampara Lobby | D51: SUMINISTRO de Placas eléctricas | E51: SUMINISTRO DE Tapajunta Metálica | F51: Piso SPC (importación) | G51: SC Drywall
A52: SC Puertas Corta Fuego | B52: Piso SPC (importación) | C52: SC Puertas Ducto Montantes | D52: SC Impermeabilización de jardineras | E52: SC INSTALACION DE PISO LAMINADO | F52: SC Mampara Lobby (ALCANDE DE 5.1)
A53: SC Ascensor(MO) | B53: SC Mampara Lobby | C53: SC Puertas Corta Fuego | D53: SC Sistema DACI a todo costo | E53: SC Muebles cocina a todo costo | F53: SC Puertas Ducto Montantes (Puertas de Melamine)
A54: Piso SPC (importación) | B54: SC Puertas Ducto Montantes | C54: SC Ascensor(MO) | D54: SC Sistema CCTV y COMUNICACIONES a todo costo | E54: SC Tableros de cocina a todo costo (importación) | F54: SC Puertas Corta Fuego
A55: SC Pisos SPC (MO) | B55: SC Puertas Corta Fuego | C55: SC Pisos SPC (MO) | D55: SC JUNTA METÁLICA | E55: SC Tableros de Baño a todo costo (importación) | F55: SC Ascensor(MO)
A56: SC Ladrillo Rococho | B56: SC Ascensor(MO) | C56: SC Ladrillo Rococho | D56: SC IMPLEMENTACION de Areas Comunes a todo costo | E56: SC Puertas de melamina en ductos a todo costo | F56: SC Pisos SPC (MO)
A57: SC Concreto expuesto | B57: Ascensor de Vehiculos | C57: SC Concreto expuesto | D57: SC PAISAJISMO a todo costo | E57: SUMINISTRO de Placas eléctricas | F57: SC Ladrillo Rococho
A58: SC de Central de Alarma Contra incendio(equipamiento) | B58: SC Pisos SPC (MO) | C58: SC de Vigas Metálicas Decorativas | D58: SC SUMINISTRO DE LUMINARIA EN SOTANOS Y TORRE | E58: SC Impermeabilización de jardineras | F58: SC Concreto expuesto
A59: SC de Intercomunicadores | B59: SC MICROCEMENTO | C59: SC de Central de Alarma Contra incendio(equipamiento) | D59: SC SUMINISTRO E INST. DE PUERTA VEHICULAR a todo costo | E59: SC Sistema DACI a todo costo | F59: SC de Central de Alarma Contra incendio(equipamiento)
A60: SC Domótica (redes y equipamiento) | B60: Grupo electrógeno para Propietarios. | C60: SC de Intercomunicadores | D60: SC LIMPIEZA FINA Y GRUESA a todo costo | E60: SC Sistema CCTV y COMUNICACIONES a todo costo | F60: SC de Intercomunicadores
A61: CCTV (redes) | B61: SC de Central de Alarma Contra incendio(equipamiento) | C61: SC Domótica (redes y equipamiento) | D61: SUMINISTRO E INSTALACION DE SEÑALETICA | E61: SC JUNTA METÁLICA | F61: SC Domótica (redes y equipamiento) (NO ES ALCANCE DE 5.2)
A62: CCTV (Equipamiento) | B62: SC de Intercomunicadores | C62: CCTV (redes) | D62: SUMINISTRO E INSTALACION DE LAVASECA | E62: SC IMPLEMENTACION de Areas Comunes a todo costo | F62: CCTV (redes)
A63: SC de Paneles Fotovoltaicos | B63: SC Domótica (redes y equipamiento) | C63: CCTV (Equipamiento) | D63: SUMINISTRO E INSTALACION DE PARRILLA DE INOX | E63: SC PAISAJISMO a todo costo | F63: CCTV (Equipamiento)
A64: SC Impermeabilización Jardineras | B64: CCTV (redes) | C64: SC de Paneles Fotovoltaicos | E64: SC SUMINISTRO DE LUMINARIA EN SOTANOS Y TORRE | F64: SC de Paneles Fotovoltaicos (NO ES ALCANCE DE 5.2)
A65: SC Áreas Verdes | B65: CCTV (Equipamiento) | C65: SC Impermeabilización Jardineras | E65: SC SUMINISTRO E INST. DE PUERTA VEHICULAR a todo costo | F65: SC Impermeabilización Jardineras
A66: SC Mueble Counter | B66: SC Impermeabilización Jardineras | C66: SC Áreas Verdes | E66: SC LIMPIEZA FINA Y GRUESA a todo costo | F66: SC Áreas Verdes
A67: SC Puerta de cochera | B67: SC Áreas Verdes | C67: SC Mueble Counter | E67: SUMINISTRO E INSTALACION DE SEÑALETICA | F67: SC Mueble Counter (NO ES ALCANCE DE 5.2)
A68: Luminarias Sótanos | B68: SC Mueble Counter | C68: SC Puerta de cochera | E68: SUMINISTRO E INSTALACION DE LAVASECA | F68: SC Puerta de cochera (NO ES ALCANCE DE 5.2)
A69: Luminaria Área Común | B69: SC Puerta de cochera | C69: Luminarias Sótanos | E69: SUMINISTRO E INSTALACION DE PARRILLA DE INOX | F69: Luminarias Sótanos
A70: SC Pintura Trafico | B70: Acabado WPC y HPL | C70: Luminaria Área Común | E70: SUMINISTRO E INSTALACION DE GRUPO ELECTRÓGENO | F70: Luminaria Área Común
B71: Sellos Cortafuego | C71: SC Pintura Trafico | F71: SC Pintura Trafico
B72: Luminarias Sótanos | C72: CS Limpieza fina
B73: Luminaria Área Común | C73: SC Tope llantas
B74: Acabados para lobby | C74: SC Señaletica
B75: Acabados para terraza | C75: SC Esquineros
B76: Acabados para sala de niños | C76: SC Acabados lobby
B77: Acabados para gymnacio | C77: SC Obras Exteriores
B78: Acabados sala bar | C78: SC de techo ducto
...

Sheet HITOS
B2: Fechas Hito para el cumplimiento del Plan de Procura | G2: 17 PISOS + 1 AZOTEA + 1 SOTANO (2 PIT ASCENSOR)
A4: Obra | B4: Fases de la Obra | C4: Fecha | E4: Fecha | F4: Observación
A5: OBRA 1 | B5: INICIO DE OBRA | D5: =A5&"xx"&B5 -> OBRA 1xxINICIO DE OBRA | E5: =C5 -> 0
A7: OBRA 1 | B7: FIN MUROS ANCLADOS | D7: =A7&"xx"&B7 -> OBRA 1xxFIN MUROS ANCLADOS | E7: =C7 -> 0
A8: OBRA 1 | B8: FIN DE SÓTANOS Y CISTERNA | D8: =A8&"xx"&B8 -> OBRA 1xxFIN DE SÓTANOS Y CISTERNA | E8: =C8 -> 0
A9: OBRA 1 | B9: TORRE PISO 10 | D9: =A9&"xx"&B9 -> OBRA 1xxTORRE PISO 10 | E9: =C9 -> 0
A10: OBRA 1 | B10: FIN DE TORRE | D10: =A10&"xx"&B10 -> OBRA 1xxFIN DE TORRE | E10: =C10 -> 0
A11: OBRA 1 | B11: ACABADOS HÚMEDOS | D11: =A11&"xx"&B11 -> OBRA 1xxACABADOS HÚMEDOS | E11: =C11 -> 0
A12: OBRA 1 | B12: ACABADOS SECOS | D12: =A12&"xx"&B12 -> OBRA 1xxACABADOS SECOS | E12: =C12 -> 0
A14: Obra | B14: Fases de la Obra | C14: Fecha | E14: Fecha | F14: Observación
A15: OBRA | B15: INICIO DE OBRA | D15: =A15&"xx"&B15 -> OBRAxxINICIO DE OBRA | E15: 46272
A16: OBRA | B16: FIN DE MUROS ANCLADOS | D16: =A16&"xx"&B16 -> OBRAxxFIN DE MUROS ANCLADOS | E16: 46305
A17: OBRA | B17: FIN DE SOTANOS | D17: =A17&"xx"&B17 -> OBRAxxFIN DE SOTANOS | E17: 46343
A18: OBRA | B18: TORRE PISO 17 | D18: =A18&"xx"&B18 -> OBRAxxTORRE PISO 17 | E18: 46346
A19: OBRA | B19: FIN DE TORRE | D19: =A19&"xx"&B19 -> OBRAxxFIN DE TORRE | E19: 46452
A20: OBRA | B20: ACABADOS HUMEDOS EN TORRE | D20: =A20&"xx"&B20 -> OBRAxxACABADOS HUMEDOS EN TORRE | E20: 46391
A21: OBRA | B21: ACABADOS SECOS EN TORRE | D21: =A21&"xx"&B21 -> OBRAxxACABADOS SECOS EN TORRE | E21: 46371
A22: OBRA | B22: ENTREGA DE DPTOS TORRE 3 | D22: =A22&"xx"&B22 -> OBRAxxENTREGA DE DPTOS TORRE 3 | E22: 46755

Sheet CRONOG 4.3
BK2: INICIA TORRE | BM2: FIN DE CASCO SOTANO | CI2: CARP MET ESCALERA | CT2: CARP MET DPTOS | CZ2: INICIA ACAB. HUMEDOS | FA2: FIN DE CASCO TORRE | HW2: INICIA ACABADO SECOS | OZ2: ENTREGA DPTOS
A3: OBRA | B3: =YEAR(B5) -> 2026 | C3: =YEAR(C5) -> 2026 | D3: =YEAR(D5) -> 2026 | E3: =YEAR(E5) -> 2026 | F3: =YEAR(F5) -> 2026 | G3: =YEAR(G5) -> 2026 | H3: =YEAR(H5) -> 2026 | I3: =YEAR(I5) -> 2026 | ... QI3: =YEAR(QI5) -> 2028
K4: mes 1
B5: 46272 | C5: =+B5+1 -> 46273 | D5: =+C5+1 -> 46274 | E5: =+D5+1 -> 46275 | F5: =+E5+1 -> 46276 | G5: =+F5+1 -> 46277 | H5: =+G5+2 -> 46279 | I5: =+H5+1 -> 46280 | J5: =+I5+1 -> 46281 | K5: =+J5+1 -> 46282 | L5: =+K5+1 -> 46283 | M5: =+L5+1 -> 46284 | N5: =+M5+2 -> 46286 | O5: =+N5+1 -> 46287 | P5: =+O5+1 -> 46288 | Q5: =+P5+1 -> 46289 | R5: =+Q5+1 -> 46290 | S5: =+R5+1 -> 46291 | T5: =+S5+2 -> 46293 | U5: =+T5+1 -> 46294 | V5: =+U5+1 -> 46295 | W5: =+V5+1 -> 46296 | X5: =+W5+1 -> 46297 | Y5: =+X5+1 -> 46298 | Z5: =+Y5+2 -> 46300 | AA5: =+Z5+1 -> 46301 | AB5: =+AA5+1 -> 46302 | AC5: =+AB5+1 -> 46303 | AD5: =+AC5+1 -> 46304 | AE5: =+AD5+1 -> 46305 | AF5: =+AE5+2 -> 46307 | AG5: =+AF5+1 -> 46308 | AH5: =+AG5+1 -> 46309 | AI5: =+AH5+1 -> 46310 | AJ5: =+AI5+1 -> 46311 | AK5: =+AJ5+1 -> 46312 | AL5: =+AK5+2 -> 46314 | AM5: =+AL5+1 -> 46315 | AN5: =+AM5+1 -> 46316 | AO5: =+AN5+1 -> 46317 | AP5: =+AO5+1 -> 46318 | AQ5: =+AP5+1 -> 46319 | AR5: =+AQ5+2 -> 46321 | AS5: =+AR5+1 -> 46322 | AT5: =+AS5+1 -> 46323 | AU5: =+AT5+1 -> 46324 | AV5: =+AU5+1 -> 46325 | AW5: =+AV5+1 -> 46326 | AX5: =+AW5+2 -> 46328 | AY5: =+AX5+1 -> 46329 | AZ5: =+AY5+1 -> 46330 | BA5: =+AZ5+1 -> 46331 | BB5: =+BA5+1 -> 46332 | BC5: =+BB5+1 -> 46333 | BD5: =+BC5+2 -> 46335 | BE5: =+BD5+1 -> 46336 | BF5: =+BE5+1 -> 46337 | BG5: =+BF5+1 -> 46338 | BH5: =+BG5+1 -> 46339 | BI5: =+BH5+1 -> 46340 | BJ5: =+BI5+2 -> 46342 | BK5: =+BJ5+1 -> 46343 | BL5: =+BK5+1 -> 46344 | BM5: =+BL5+1 -> 46345 | BN5: =+BM5+1 -> 46346 | BO5: =+BN5+1 -> 46347 | BP5: =+BO5+2 -> 46349 | BQ5: =+BP5+1 -> 46350 | BR5: =+BQ5+1 -> 46351 | BS5: =+BR5+1 -> 46352 | BT5: =+BS5+1 -> 46353 | BU5: =+BT5+1 -> 46354 | BV5: =+BU5+2 -> 46356 | BW5: =+BV5+1 -> 46357 | BX5: =+BW5+1 -> 46358 | BY5: =+BX5+1 -> 46359 | BZ5: =+BY5+1 -> 46360 | CA5: =+BZ5+1 -> 46361 | CB5: =+CA5+2 -> 46363 | CC5: =+CB5+1 -> 46364 | CD5: =+CC5+1 -> 46365 | CE5: =+CD5+1 -> 46366 | CF5: =+CE5+1 -> 46367 | CG5: =+CF5+1 -> 46368 | CH5: =+CG5+2 -> 46370 | CI5: =+CH5+1 -> 46371 | CJ5: =+CI5+1 -> 46372 | CK5: =+CJ5+1 -> 46373 | CL5: =+CK5+1 -> 46374 | CM5: =+CL5+1 -> 46375 | CN5: =+CM5+2 -> 46377 | CO5: =+CN5+1 -> 46378 | CP5: =+CO5+1 -> 46379 | CQ5: =+CP5+1 -> 46380 | CR5: =+CQ5+1 -> 46381 | CS5: =+CR5+1 -> 46382 | CT5: =+CS5+2 -> 46384 | CU5: =+CT5+1 -> 46385 | CV5: =+CU5+1 -> 46386 | CW5: =+CV5+1 -> 46387 | CX5: =+CW5+1 -> 46388 | CY5: =+CX5+1 -> 46389 | CZ5: =+CY5+2 -> 46391 | DA5: =+CZ5+1 -> 46392 | DB5: =+DA5+1 -> 46393 | DC5: =+DB5+1 -> 46394 | DD5: =+DC5+1 -> 46395 | DE5: =+DD5+1 -> 46396 | DF5: =+DE5+2 -> 46398 | DG5: =+DF5+1 -> 46399 | DH5: =+DG5+1 -> 46400 | DI5: =+DH5+1 -> 46401 | DJ5: =+DI5+1 -> 46402 | DK5: =+DJ5+1 -> 46403 | DL5: =+DK5+2 -> 46405 | DM5: =+DL5+1 -> 46406 | DN5: =+DM5+1 -> 46407 | DO5: =+DN5+1 -> 46408 | DP5: =+DO5+1 -> 46409 | DQ5: =+DP5+1 -> 46410 | DR5: =+DQ5+2 -> 46412 | DS5: =+DR5+1 -> 46413 | DT5: =+DS5+1 -> 46414 | DU5: =+DT5+1 -> 46415 | DV5: =+DU5+1 -> 46416 | DW5: =+DV5+1 -> 46417 | DX5: =+DW5+2 -> 46419 | DY5: =+DX5+1 -> 46420 | DZ5: =+DY5+1 -> 46421 | EA5: =+DZ5+1 -> 46422 | EB5: =+EA5+1 -> 46423 | EC5: =+EB5+1 -> 46424 | ED5: =+EC5+2 -> 46426 | EE5: =+ED5+1 -> 46427 | EF5: =+EE5+1 -> 46428 | EG5: =+EF5+1 -> 46429 | EH5: =+EG5+1 -> 46430 | EI5: =+EH5+1 -> 46431 | EJ5: =+EI5+2 -> 46433 | EK5: =+EJ5+1 -> 46434 | EL5: =+EK5+1 -> 46435 | EM5: =+EL5+1 -> 46436 | EN5: =+EM5+1 -> 46437 | EO5: =+EN5+1 -> 46438 | EP5: =+EO5+2 -> 46440 | EQ5: =+EP5+1 -> 46441 | ER5: =+EQ5+1 -> 46442 | ES5: =+ER5+1 -> 46443 | ET5: =+ES5+1 -> 46444 | EU5: =+ET5+1 -> 46445 | EV5: =+EU5+2 -> 46447 | EW5: =+EV5+1 -> 46448 | EX5: =+EW5+1 -> 46449 | EY5: =+EX5+1 -> 46450 | EZ5: =+EY5+1 -> 46451 | FA5: =+EZ5+1 -> 46452 | FB5: =+FA5+2 -> 46454 | FC5: =+FB5+1 -> 46455 | FD5: =+FC5+1 -> 46456 | FE5: =+FD5+1 -> 46457 | FF5: =+FE5+1 -> 46458 | FG5: =+FF5+1 -> 46459 | FH5: =+FG5+2 -> 46461 | FI5: =+FH5+1 -> 46462 | FJ5: =+FI5+1 -> 46463 | FK5: =+FJ5+1 -> 46464 | FL5: =+FK5+1 -> 46465 | FM5: =+FL5+1 -> 46466 | FN5: =+FM5+2 -> 46468 | FO5: =+FN5+1 -> 46469 | FP5: =+FO5+1 -> 46470 | FQ5: =+FP5+1 -> 46471 | FR5: =+FQ5+1 -> 46472 | FS5: =+FR5+1 -> 46473 | FT5: =+FS5+2 -> 46475 | FU5: =+FT5+1 -> 46476 | FV5: =+FU5+1 -> 46477 | FW5: =+FV5+1 -> 46478 | FX5: =+FW5+1 -> 46479 | FY5: =+FX5+1 -> 46480 | FZ5: =+FY5+2 -> 46482 | GA5: =+FZ5+1 -> 46483 | GB5: =+GA5+1 -> 46484 | GC5: =+GB5+1 -> 46485 | GD5: =+GC5+1 -> 46486 | GE5: =+GD5+1 -> 46487 | GF5: =+GE5+2 -> 46489 | GG5: =+GF5+1 -> 46490 | GH5: =+GG5+1 -> 46491 | GI5: =+GH5+1 -> 46492 | GJ5: =+GI5+1 -> 46493 | GK5: =+GJ5+1 -> 46494 | GL5: =+GK5+2 -> 46496 | GM5: =+GL5+1 -> 46497 | GN5: =+GM5+1 -> 46498 | GO5: =+GN5+1 -> 46499 | GP5: =+GO5+1 -> 46500 | GQ5: =+GP5+1 -> 46501 | GR5: =+GQ5+2 -> 46503 | GS5: =+GR5+1 -> 46504 | GT5: =+GS5+1 -> 46505 | GU5: =+GT5+1 -> 46506 | GV5: =+GU5+1 -> 46507 | GW5: =+GV5+1 -> 46508 | GX5: =+GW5+2 -> 46510 | GY5: =+GX5+1 -> 46511 | GZ5: =+GY5+1 -> 46512 | HA5: =+GZ5+1 -> 46513 | HB5: =+HA5+1 -> 46514 | HC5: =+HB5+1 -> 46515 | HD5: =+HC5+2 -> 46517 | HE5: =+HD5+1 -> 46518 | HF5: =+HE5+1 -> 46519 | HG5: =+HF5+1 -> 46520 | HH5: =+HG5+1 -> 46521 | HI5: =+HH5+1 -> 46522 | HJ5: =+HI5+2 -> 46524 | HK5: =+HJ5+1 -> 46525 | HL5: =+HK5+1 -> 46526 | HM5: =+HL5+1 -> 46527 | HN5: =+HM5+1 -> 46528 | HO5: =+HN5+1 -> 46529 | HP5: =+HO5+2 -> 46531 | HQ5: =+HP5+1 -> 46532 | HR5: =+HQ5+1 -> 46533 | HS5: =+HR5+1 -> 46534 | HT5: =+HS5+1 -> 46535 | HU5: =+HT5+1 -> 46536 | HV5: =+HU5+2 -> 46538 | HW5: =+HV5+1 -> 46539 | HX5: =+HW5+1 -> 46540 | HY5: =+HX5+1 -> 46541 | HZ5: =+HY5+1 -> 46542 | IA5: =+HZ5+1 -> 46543 | IB5: =+IA5+2 -> 46545 | IC5: =+IB5+1 -> 46546 | ID5: =+IC5+1 -> 46547 | IE5: =+ID5+1 -> 46548 | IF5: =+IE5+1 -> 46549 | IG5: =+IF5+1 -> 46550 | IH5: =+IG5+2 -> 46552 | II5: =+IH5+1 -> 46553 | IJ5: =+II5+1 -> 46554 | IK5: =+IJ5+1 -> 46555 | IL5: =+IK5+1 -> 46556 | IM5: =+IL5+1 -> 46557 | IN5: =+IM5+2 -> 46559 | IO5: =+IN5+1 -> 46560 | IP5: =+IO5+1 -> 46561 | IQ5: =+IP5+1 -> 46562 | IR5: =+IQ5+1 -> 46563 | IS5: =+IR5+1 -> 46564 | IT5: =+IS5+2 -> 46566 | IU5: =+IT5+1 -> 46567 | IV5: =+IU5+1 -> 46568 | IW5: =+IV5+1 -> 46569 | IX5: =+IW5+1 -> 46570 | IY5: =+IX5+1 -> 46571 | IZ5: =+IY5+2 -> 46573 | JA5: =+IZ5+1 -> 46574 | JB5: =+JA5+1 -> 46575 | JC5: =+JB5+1 -> 46576 | JD5: =+JC5+1 -> 46577 | JE5: =+JD5+1 -> 46578 | JF5: =+JE5+2 -> 46580 | JG5: =+JF5+1 -> 46581 | JH5: =+JG5+1 -> 46582 | JI5: =+JH5+1 -> 46583 | JJ5: =+JI5+1 -> 46584 | JK5: =+JJ5+1 -> 46585 | JL5: =+JK5+2 -> 46587 | JM5: =+JL5+1 -> 46588 | JN5: =+JM5+1 -> 46589 | JO5: =+JN5+1 -> 46590 | JP5: =+JO5+1 -> 46591 | JQ5: =+JP5+1 -> 46592 | JR5: =+JQ5+2 -> 46594 | JS5: =+JR5+1 -> 46595 | JT5: =+JS5+1 -> 46596 | JU5: =+JT5+1 -> 46597 | JV5: =+JU5+1 -> 46598 | JW5: =+JV5+1 -> 46599 | JX5: =+JW5+2 -> 46601 | JY5: =+JX5+1 -> 46602 | JZ5: =+JY5+1 -> 46603 | KA5: =+JZ5+1 -> 46604 | KB5: =+KA5+1 -> 46605 | KC5: =+KB5+1 -> 46606 | KD5: =+KC5+2 -> 46608 | KE5: =+KD5+1 -> 46609 | KF5: =+KE5+1 -> 46610 | KG5: =+KF5+1 -> 46611 | KH5: =+KG5+1 -> 46612 | KI5: =+KH5+1 -> 46613 | KJ5: =+KI5+2 -> 46615 | KK5: =+KJ5+1 -> 46616 | KL5: =+KK5+1 -> 46617 | KM5: =+KL5+1 -> 46618 | KN5: =+KM5+1 -> 46619 | KO5: =+KN5+1 -> 46620 | KP5: =+KO5+2 -> 46622 | KQ5: =+KP5+1 -> 46623 | KR5: =+KQ5+1 -> 46624 | KS5: =+KR5+1 -> 46625 | KT5: =+KS5+1 -> 46626 | KU5: =+KT5+1 -> 46627 | KV5: =+KU5+2 -> 46629 | KW5: =+KV5+1 -> 46630 | KX5: =+KW5+1 -> 46631 | KY5: =+KX5+1 -> 46632 | KZ5: =+KY5+1 -> 46633 | LA5: =+KZ5+1 -> 46634 | LB5: =+LA5+2 -> 46636 | LC5: =+LB5+1 -> 46637 | LD5: =+LC5+1 -> 46638 | LE5: =+LD5+1 -> 46639 | LF5: =+LE5+1 -> 46640 | LG5: =+LF5+1 -> 46641 | LH5: =+LG5+2 -> 46643 | LI5: =+LH5+1 -> 46644 | LJ5: =+LI5+1 -> 46645 | LK5: =+LJ5+1 -> 46646 | LL5: =+LK5+1 -> 46647 | LM5: =+LL5+1 -> 46648 | LN5: =+LM5+2 -> 46650 | LO5: =+LN5+1 -> 46651 | LP5: =+LO5+1 -> 46652 | LQ5: =+LP5+1 -> 46653 | LR5: =+LQ5+1 -> 46654 | LS5: =+LR5+1 -> 46655 | LT5: =+LS5+2 -> 46657 | LU5: =+LT5+1 -> 46658 | LV5: =+LU5+1 -> 46659 | LW5: =+LV5+1 -> 46660 | LX5: =+LW5+1 -> 46661 | LY5: =+LX5+1 -> 46662 | LZ5: =+LY5+2 -> 46664 | MA5: =+LZ5+1 -> 46665 | MB5: =+MA5+1 -> 46666 | MC5: =+MB5+1 -> 46667 | MD5: =+MC5+1 -> 46668 | ME5: =+MD5+1 -> 46669 | MF5: =+ME5+2 -> 46671 | MG5: =+MF5+1 -> 46672 | MH5: =+MG5+1 -> 46673 | MI5: =+MH5+1 -> 46674 | MJ5: =+MI5+1 -> 46675 | MK5: =+MJ5+1 -> 46676 | ML5: =+MK5+2 -> 46678 | MM5: =+ML5+1 -> 46679 | MN5: =+MM5+1 -> 46680 | MO5: =+MN5+1 -> 46681 | MP5: =+MO5+1 -> 46682 | MQ5: =+MP5+1 -> 46683 | MR5: =+MQ5+2 -> 46685 | MS5: =+MR5+1 -> 46686 | MT5: =+MS5+1 -> 46687 | MU5: =+MT5+1 -> 46688 | MV5: =+MU5+1 -> 46689 | MW5: =+MV5+1 -> 46690 | MX5: =+MW5+2 -> 46692 | MY5: =+MX5+1 -> 46693 | MZ5: =+MY5+1 -> 46694 | NA5: =+MZ5+1 -> 46695 | NB5: =+NA5+1 -> 46696 | NC5: =+NB5+1 -> 46697 | ND5: =+NC5+2 -> 46699 | NE5: =+ND5+1 -> 46700 | NF5: =+NE5+1 -> 46701 | NG5: =+NF5+1 -> 46702 | NH5: =+NG5+1 -> 46703 | NI5: =+NH5+1 -> 46704 | NJ5: =+NI5+2 -> 46706 | NK5: =+NJ5+1 -> 46707 | NL5: =+NK5+1 -> 46708 | NM5: =+NL5+1 -> 46709 | NN5: =+NM5+1 -> 46710 | NO5: =+NN5+1 -> 46711 | NP5: =+NO5+2 -> 46713 | NQ5: =+NP5+1 -> 46714 | NR5: =+NQ5+1 -> 46715 | NS5: =+NR5+1 -> 46716 | NT5: =+NS5+1 -> 46717 | NU5: =+NT5+1 -> 46718 | NV5: =+NU5+2 -> 46720 | NW5: =+NV5+1 -> 46721 | NX5: =+NW5+1 -> 46722 | NY5: =+NX5+1 -> 46723 | NZ5: =+NY5+1 -> 46724 | OA5: =+NZ5+1 -> 46725 | OB5: =+OA5+2 -> 46727 | OC5: =+OB5+1 -> 46728 | OD5: =+OC5+1 -> 46729 | OE5: =+OD5+1 -> 46730 | OF5: =+OE5+1 -> 46731 | OG5: =+OF5+1 -> 46732 | OH5: =+OG5+2 -> 46734 | OI5: =+OH5+1 -> 46735 | OJ5: =+OI5+1 -> 46736 | OK5: =+OJ5+1 -> 46737 | OL5: =+OK5+1 -> 46738 | OM5: =+OL5+1 -> 46739 | ON5: =+OM5+2 -> 46741 | OO5: =+ON5+1 -> 46742 | OP5: =+OO5+1 -> 46743 | OQ5: =+OP5+1 -> 46744 | OR5: =+OQ5+1 -> 46745 | OS5: =+OR5+1 -> 46746 | OT5: =+OS5+2 -> 46748 | OU5: =+OT5+1 -> 46749 | OV5: =+OU5+1 -> 46750 | OW5: =+OV5+1 -> 46751 | OX5: =+OW5+1 -> 46752 | OY5: =+OX5+1 -> 46753 | OZ5: =+OY5+2 -> 46755 | PA5: =+OZ5+1 -> 46756 | PB5: =+PA5+1 -> 46757 | PC5: =+PB5+1 -> 46758 | PD5: =+PC5+1 -> 46759 | PE5: =+PD5+1 -> 46760 | PF5: =+PE5+2 -> 46762 | PG5: =+PF5+1 -> 46763 | PH5: =+PG5+1 -> 46764 | PI5: =+PH5+1 -> 46765 | PJ5: =+PI5+1 -> 46766 | PK5: =+PJ5+1 -> 46767 | PL5: =+PK5+2 -> 46769 | PM5: =+PL5+1 -> 46770 | PN5: =+PM5+1 -> 46771 | PO5: =+PN5+1 -> 46772 | PP5: =+PO5+1 -> 46773 | PQ5: =+PP5+1 -> 46774 | PR5: =+PQ5+2 -> 46776 | PS5: =+PR5+1 -> 46777 | PT5: =+PS5+1 -> 46778 | PU5: =+PT5+1 -> 46779 | PV5: =+PU5+1 -> 46780 | PW5: =+PV5+1 -> 46781 | PX5: =+PW5+2 -> 46783 | PY5: =+PX5+1 -> 46784 | PZ5: =+PY5+1 -> 46785 | QA5: =+PZ5+1 -> 46786 | QB5: =+QA5+1 -> 46787 | QC5: =+QB5+1 -> 46788 | QD5: =+QC5+2 -> 46790 | QE5: =+QD5+1 -> 46791 | QF5: =+QE5+1 -> 46792 | QG5: =+QF5+1 -> 46793 | QH5: =+QG5+1 -> 46794 | QI5: =+QH5+1 -> 46795
B6: =UPPER(TEXT(B5,"ddd")) -> LUN | C6: =UPPER(TEXT(C5,"ddd")) -> MAR | D6: =UPPER(TEXT(D5,"ddd")) -> MIÉ | E6: =UPPER(TEXT(E5,"ddd")) -> JUE | F6: =UPPER(TEXT(F5,"ddd")) -> VIE | G6: =UPPER(TEXT(G5,"ddd")) -> SÁB | H6: =UPPER(TEXT(H5,"ddd")) -> LUN | I6: =UPPER(TEXT(I5,"ddd")) -> MAR | ... QI6: =UPPER(TEXT(QI5,"ddd")) -> SÁB
A8: CAMPAMENTO / IMPLENTACION DE OFICINAS
A9: MOVILIZACION EQUIPO / PERSONAL
A10: DEMOLICION
A12: EXCAVACION / MURO PANTALLA (INC PERNOS DE ANCLAJE)
A13: ANILLO 1 - 217 | N13: S1,1 | O13: S1,2 | P13: S1,3 | Q13: S1,4 | R13: S1,5 | S13: S1,6 | T13: S1,7 | U13: S1,8 | V13: S1,9 | W13: S1,10 | X13: S1,11 | Y13: S1,12 | Z13: S1,13 | AA13: S1,14 | AB13: S1,15 | AD13: S1,16 | AE13: S1,17 | AF13: S1,18 | AG13: S1,19 | AH13: S1,20 | AI13: S1,21 | AJ13: S1,22 | AK13: S1,23 | AL13: S1,24
N14: 1 | O14: 2 | P14: 3 | Q14: 4 | R14: 5 | S14: 6 | T14: 7 | U14: 8 | V14: 9 | W14: 10 | X14: 11 | Y14: 12 | Z14: 13 | AA14: 14 | AB14: 15 | AD14: 16 | AE14: 17 | AF14: 18 | AG14: 19 | AH14: 20 | AI14: 21 | AJ14: 22 | AK14: 23 | AL14: 24
A15: EXCAVACION MASIVA
A16: PERFORACIONES / ANCLAJE
A17: EXCAVACION LOCALIZADA
A18: PAÑETEO
A19: ACERO MURO CONTENCION
A20: ENCOFRADO MURO CONTENCION
A21: CONCRETO MURO CONTENCION
A22: TENSADO CABLES
A23: MURO DE CONTENCION | AM23: S2,1 | AN23: S2,2 | AO23: S2,3 | AP23: S2,4 | AQ23: S2,5 | AS23: S2,6 | AT23: S2,13 | AU23: S2,14 | AV23: S2,15 | AW23: S2,16 | AX23: S2,17 | AY23: S2,18 | AZ23: S2,19 | BA23: S2,20 | BB23: S2,21 | BC23: S2,22 | BD23: S2,23 | BE23: S2,24
AM24: 1 | AN24: 2 | AO24: 3 | AP24: 4 | AQ24: 5 | AS24: 6 | AT24: 7 | AU24: 8 | AV24: 9 | AW24: 10 | AX24: 11 | AY24: 12 | AZ24: 13 | BA24: 14 | BB24: 15 | BC24: 16 | BD24: 17 | BE24: 18
A25: EXCAVACION MASIVA
A26: EXCAVACION LOCALIZADA
A27: PAÑETEO
A28: ACERO MURO CONTENCION
A29: ENCOFRADO MURO CONTENCION
A30: CONCRETO MURO CONTENCION
A32: CIMIENTOS INTERIORES | AZ32: C | BA32: C | BB32: C | BC32: C | BD32: C | BE32: C | BF32: C | BG32: C | BH32: C | BI32: C | BJ32: C | BK32: C | BL32: C
A35: ESTRUCTURAS
A36: ELEMENTOS VERTICALES
A37: ACERO EN PLACAS | BF37: S11 | BG37: S12 | BH37: S13 | BI37: S14 | BJ37: S15 | BK37: E11 | BL37: E12 | BM37: E13 | BN37: E,14 | BO37: E,15 | BP37: E21 | BQ37: E22 | BR37: E23 | BS37: E24 | BT37: E25 | BU37: E31 | BV37: E32 | BW37: E33 | BX37: E34 | BY37: E35 | BZ37: E41 | CA37: E42 | CB37: E43 | CE37: E44 | CF37: E45 | CG37: E51 | CH37: E52 | CI37: E53 | CJ37: E54 | CK37: E55 | CL37: E61 | CM37: E62 | CN37: E63 | CO37: E64 | CP37: E65 | CQ37: E71 | CS37: E72 | CT37: E73 | CU37: E74 | CV37: E75 | CW37: E81 | CY37: E82 | CZ37: E83 | DA37: E84 | DB37: E85 | DC37: E91 | DD37: E92 | DE37: E93 | DF37: E94 | DG37: E95 | DH37: E101 | DI37: E102 | DJ37: E103 | DK37: E104 | DL37: E105 | DM37: E111 | DN37: E112 | DO37: E113 | DP37: E114 | DQ37: E115 | DR37: E121 | DS37: E122 | DT37: E123 | DU37: E124 | DV37: E125 | DW37: E1231 | DX37: E132 | DY37: E133 | DZ37: E134 | EA37: E135 | EB37: E141 | EC37: E142 | ED37: E143 | EE37: E144 | EF37: E145 | EG37: E151 | EH37: E152 | EI37: E153 | EJ37: E154 | EK37: E155 | EL37: E161 | EM37: E162 | EN37: E163 | EO37: E164 | EP37: E165 | EQ37: E171 | ER37: E172 | ES37: E173 | ET37: E174 | EU37: E175 | EV37: E181 | EW37: E182 | EX37: E183
A38: IIEE IISS DE MUROS | BF38: S11 | BG38: S12 | BH38: S13 | BI38: S14 | BJ38: S15 | BK38: E11 | BL38: E12 | BM38: E13 | BN38: E,14 | BO38: E,15 | BP38: E21 | BQ38: E22 | BR38: E23 | BS38: E24 | BT38: E25 | BU38: E31 | BV38: E32 | BW38: E33 | BX38: E34 | BY38: E35 | BZ38: E41 | CA38: E42 | CB38: E43 | CE38: E44 | CF38: E45 | CG38: E51 | CH38: E52 | CI38: E53 | CJ38: E54 | CK38: E55 | CL38: E61 | CM38: E62 | CN38: E63 | CO38: E64 | CP38: E65 | CQ38: E71 | CS38: E72 | CT38: E73 | CU38: E74 | CV38: E75 | CW38: E81 | CY38: E82 | CZ38: E83 | DA38: E84 | DB38: E85 | DC38: E91 | DD38: E92 | DE38: E93 | DF38: E94 | DG38: E95 | DH38: E101 | DI38: E102 | DJ38: E103 | DK38: E104 | DL38: E105 | DM38: E111 | DN38: E112 | DO38: E113 | DP38: E114 | DQ38: E115 | DR38: E121 | DS38: E122 | DT38: E123 | DU38: E124 | DV38: E125 | DW38: E1231 | DX38: E132 | DY38: E133 | DZ38: E134 | EA38: E135 | EB38: E141 | EC38: E142 | ED38: E143 | EE38: E144 | EF38: E145 | EG38: E151 | EH38: E152 | EI38: E153 | EJ38: E154 | EK38: E155 | EL38: E161 | EM38: E162 | EN38: E163 | EO38: E164 | EP38: E165 | EQ38: E171 | ER38: E172 | ES38: E173 | ET38: E174 | EU38: E175 | EV38: E181 | EW38: E182 | EX38: E183
A39: ENCOFRADO EN PLACAS | BG39: S11 | BH39: S12 | BI39: S13 | BJ39: S14 | BK39: S15 | BL39: E11 | BM39: E12 | BN39: E13 | BO39: E,14 | BP39: E,15 | BQ39: E21 | BR39: E22 | BS39: E23 | BT39: E24 | BU39: E25 | BV39: E31 | BW39: E32 | BX39: E33 | BY39: E34 | BZ39: E35 | CA39: E41 | CB39: E42 | CE39: E43 | CF39: E44 | CG39: E45 | CH39: E51 | CI39: E52 | CJ39: E53 | CK39: E54 | CL39: E55 | CM39: E61 | CN39: E62 | CO39: E63 | CP39: E64 | CQ39: E65 | CS39: E71 | CT39: E72 | CU39: E73 | CV39: E74 | CW39: E75 | CY39: E81 | CZ39: E82 | DA39: E83 | DB39: E84 | DC39: E85 | DD39: E91 | DE39: E92 | DF39: E93 | DG39: E94 | DH39: E95 | DI39: E101 | DJ39: E102 | DK39: E103 | DL39: E104 | DM39: E105 | DN39: E111 | DO39: E112 | DP39: E113 | DQ39: E114 | DR39: E115 | DS39: E121 | DT39: E122 | DU39: E123 | DV39: E124 | DW39: E125 | DX39: E1231 | DY39: E132 | DZ39: E133 | EA39: E134 | EB39: E135 | EC39: E141 | ED39: E142 | EE39: E143 | EF39: E144 | EG39: E145 | EH39: E151 | EI39: E152 | EJ39: E153 | EK39: E154 | EL39: E155 | EM39: E161 | EN39: E162 | EO39: E163 | EP39: E164 | EQ39: E165 | ER39: E171 | ES39: E172 | ET39: E173 | EU39: E174 | EV39: E175 | EW39: E181 | EX39: E182 | EY39: E183
A40: CONCRETO DE PLACAS | BG40: S,11 | BH40: S,12 | BI40: S,13 | BJ40: S,14 | BK40: S,15 | BL40: E11 | BM40: E12 | BN40: E13 | BO40: E,14 | BP40: E,15 | BQ40: E21 | BR40: E22 | BS40: E23 | BT40: E24 | BU40: E25 | BV40: E31 | BW40: E32 | BX40: E33 | BY40: E34 | BZ40: E35 | CA40: E41 | CB40: E42 | CE40: E43 | CF40: E44 | CG40: E45 | CH40: E51 | CI40: E52 | CJ40: E53 | CK40: E54 | CL40: E55 | CM40: E61 | CN40: E62 | CO40: E63 | CP40: E64 | CQ40: E65 | CS40: E71 | CT40: E72 | CU40: E73 | CV40: E74 | CW40: E75 | CY40: E81 | CZ40: E82 | DA40: E83 | DB40: E84 | DC40: E85 | DD40: E91 | DE40: E92 | DF40: E93 | DG40: E94 | DH40: E95 | DI40: E101 | DJ40: E102 | DK40: E103 | DL40: E104 | DM40: E105 | DN40: E111 | DO40: E112 | DP40: E113 | DQ40: E114 | DR40: E115 | DS40: E121 | DT40: E122 | DU40: E123 | DV40: E124 | DW40: E125 | DX40: E1231 | DY40: E132 | DZ40: E133 | EA40: E134 | EB40: E135 | EC40: E141 | ED40: E142 | EE40: E143 | EF40: E144 | EG40: E145 | EH40: E151 | EI40: E152 | EJ40: E153 | EK40: E154 | EL40: E155 | EM40: E161 | EN40: E162 | EO40: E163 | EP40: E164 | EQ40: E165 | ER40: E171 | ES40: E172 | ET40: E173 | EU40: E174 | EV40: E175 | EW40: E181 | EX40: E182 | EY40: E183
A41: ELEMENTOS HORIZONTALES | BF41: 1 | BG41: 2 | BH41: 3 | BI41: 4 | BJ41: 5 | BK41: 6 | BL41: 7 | BM41: 8 | BN41: 9 | BO41: 10 | BP41: 11 | BQ41: 12 | BR41: 13 | BS41: 14 | BT41: 15 | BU41: 16 | BV41: 17 | BW41: 18 | BX41: 19 | BY41: 20 | BZ41: 21 | CA41: 22 | CB41: 23 | CE41: 24 | CF41: 25 | CG41: 26 | CH41: 27 | CI41: 28 | CJ41: 29 | CK41: 30 | CL41: 31 | CM41: 32 | CN41: 33 | CO41: 34 | CP41: 35 | CQ41: 36 | CS41: 37 | CT41: 38 | CU41: 39 | CV41: 40 | CW41: 41 | CY41: 42 | CZ41: 43 | DA41: 44 | DB41: 45 | DC41: 46 | DD41: 47 | DE41: 48 | DF41: 49 | DG41: 50 | DH41: 51 | DI41: 52 | DJ41: 53 | DK41: 54 | DL41: 55 | DM41: 56 | DN41: 57 | DO41: 58 | DP41: 59 | DQ41: 60 | DR41: 61 | DS41: 62 | DT41: 63 | DU41: 64 | DV41: 65 | DW41: 66 | DX41: 67 | DY41: 68 | DZ41: 69 | EA41: 70 | EB41: 71 | EC41: 72 | ED41: 73 | EE41: 74 | EF41: 75 | EG41: 76 | EH41: 77 | EI41: 78 | EJ41: 79 | EK41: 80 | EL41: 81 | EM41: 82 | EN41: 83 | EO41: 84 | EP41: 85 | EQ41: 86 | ER41: 87 | ES41: 88 | ET41: 89 | EU41: 90 | EV41: 91 | EW41: 92 | EX41: 93 | EY41: 94 | EZ41: 95 | FA41: 96
A42: ENCOFRADO DE TECHOS | BH42: S11 | BI42: S12 | BJ42: S13 | BK42: S14 | BL42: S15 | BM42: E,11 | BN42: E1,12 | BO42: E,13 | BP42: E,14 | BQ42: E,15 | BR42: E21 | BS42: E22 | BT42: E23 | BU42: E24 | BV42: E25 | BW42: E31 | BX42: E32 | BY42: E33 | BZ42: E34 | CA42: E35 | CB42: E41 | CE42: E42 | CF42: E43 | CG42: E44 | CH42: E45 | CI42: E51 | CJ42: E52 | CK42: E53 | CL42: E54 | CM42: E55 | CN42: E61 | CO42: E62 | CP42: E63 | CQ42: E64 | CS42: E65 | CT42: E71 | CU42: E72 | CV42: E73 | CW42: E74 | CY42: E75 | CZ42: E81 | DA42: E82 | DB42: E83 | DC42: E84 | DD42: E85 | DE42: E91 | DF42: E92 | DG42: E93 | DH42: E94 | DI42: E95 | DJ42: E101 | DK42: E102 | DL42: E103 | DM42: E104 | DN42: E105 | DO42: E111 | DP42: E112 | DQ42: E113 | DR42: E114 | DS42: E115 | DT42: E121 | DU42: E122 | DV42: E123 | DW42: E124 | DX42: E125 | DY42: E1231 | DZ42: E132 | EA42: E133 | EB42: E134 | EC42: E135 | ED42: E141 | EE42: E142 | EF42: E143 | EG42: E144 | EH42: E145 | EI42: E151 | EJ42: E152 | EK42: E153 | EL42: E154 | EM42: E155 | EN42: E161 | EO42: E162 | EP42: E163 | EQ42: E164 | ER42: E165 | ES42: E171 | ET42: E172 | EU42: E173 | EV42: E174 | EW42: E175 | EX42: E181 | EY42: E182 | EZ42: E183
A43: ACERO EN TECHOS | BI43: S11 | BJ43: S12 | BK43: S13 | BL43: S14 | BM43: S15 | BN43: E,11 | BO43: E1,12 | BP43: E,13 | BQ43: E,14 | BR43: E,15 | BS43: E21 | BT43: E22 | BU43: E23 | BV43: E24 | BW43: E25 | BX43: E31 | BY43: E32 | BZ43: E33 | CA43: E34 | CB43: E35 | CE43: E41 | CF43: E42 | CG43: E43 | CH43: E44 | CI43: E45 | CJ43: E51 | CK43: E52 | CL43: E53 | CM43: E54 | CN43: E55 | CO43: E61 | CP43: E62 | CQ43: E63 | CS43: E64 | CT43: E65 | CU43: E71 | CV43: E72 | CW43: E73 | CY43: E74 | CZ43: E75 | DA43: E81 | DB43: E82 | DC43: E83 | DD43: E84 | DE43: E85 | DF43: E91 | DG43: E92 | DH43: E93 | DI43: E94 | DJ43: E95 | DK43: E101 | DL43: E102 | DM43: E103 | DN43: E104 | DO43: E105 | DP43: E111 | DQ43: E112 | DR43: E113 | DS43: E114 | DT43: E115 | DU43: E121 | DV43: E122 | DW43: E123 | DX43: E124 | DY43: E125 | DZ43: E1231 | EA43: E132 | EB43: E133 | EC43: E134 | ED43: E135 | EE43: E141 | EF43: E142 | EG43: E143 | EH43: E144 | EI43: E145 | EJ43: E151 | EK43: E152 | EL43: E153 | EM43: E154 | EN43: E155 | EO43: E161 | EP43: E162 | EQ43: E163 | ER43: E164 | ES43: E165 | ET43: E171 | EU43: E172 | EV43: E173 | EW43: E174 | EX43: E175 | EY43: E181 | EZ43: E182 | FA43: E183
A44: IIEE IISS DE TECHOS | BI44: S11 | BJ44: S12 | BK44: S13 | BL44: S14 | BM44: S15 | BN44: E,11 | BO44: E1,12 | BP44: E,13 | BQ44: E,14 | BR44: E,15 | BS44: E21 | BT44: E22 | BU44: E23 | BV44: E24 | BW44: E25 | BX44: E31 | BY44: E32 | BZ44: E33 | CA44: E34 | CB44: E35 | CE44: E41 | CF44: E42 | CG44: E43 | CH44: E44 | CI44: E45 | CJ44: E51 | CK44: E52 | CL44: E53 | CM44: E54 | CN44: E55 | CO44: E61 | CP44: E62 | CQ44: E63 | CS44: E64 | CT44: E65 | CU44: E71 | CV44: E72 | CW44: E73 | CY44: E74 | CZ44: E75 | DA44: E81 | DB44: E82 | DC44: E83 | DD44: E84 | DE44: E85 | DF44: E91 | DG44: E92 | DH44: E93 | DI44: E94 | DJ44: E95 | DK44: E101 | DL44: E102 | DM44: E103 | DN44: E104 | DO44: E105 | DP44: E111 | DQ44: E112 | DR44: E113 | DS44: E114 | DT44: E115 | DU44: E121 | DV44: E122 | DW44: E123 | DX44: E124 | DY44: E125 | DZ44: E1231 | EA44: E132 | EB44: E133 | EC44: E134 | ED44: E135 | EE44: E141 | EF44: E142 | EG44: E143 | EH44: E144 | EI44: E145 | EJ44: E151 | EK44: E152 | EL44: E153 | EM44: E154 | EN44: E155 | EO44: E161 | EP44: E162 | EQ44: E163 | ER44: E164 | ES44: E165 | ET44: E171 | EU44: E172 | EV44: E173 | EW44: E174 | EX44: E175 | EY44: E181 | EZ44: E182 | FA44: E183
A45: CONCRETO EN TECHOS | BI45: S11 | BJ45: S12 | BK45: S13 | BL45: S14 | BM45: S15 | BN45: E,11 | BO45: E1,12 | BP45: E,13 | BQ45: E,14 | BR45: E,15 | BS45: E21 | BT45: E22 | BU45: E23 | BV45: E24 | BW45: E25 | BX45: E31 | BY45: E32 | BZ45: E33 | CA45: E34 | CB45: E35 | CE45: E41 | CF45: E42 | CG45: E43 | CH45: E44 | CI45: E45 | CJ45: E51 | CK45: E52 | CL45: E53 | CM45: E54 | CN45: E55 | CO45: E61 | CP45: E62 | CQ45: E63 | CS45: E64 | CT45: E65 | CU45: E71 | CV45: E72 | CW45: E73 | CY45: E74 | CZ45: E75 | DA45: E81 | DB45: E82 | DC45: E83 | DD45: E84 | DE45: E85 | DF45: E91 | DG45: E92 | DH45: E93 | DI45: E94 | DJ45: E95 | DK45: E101 | DL45: E102 | DM45: E103 | DN45: E104 | DO45: E105 | DP45: E111 | DQ45: E112 | DR45: E113 | DS45: E114 | DT45: E115 | DU45: E121 | DV45: E122 | DW45: E123 | DX45: E124 | DY45: E125 | DZ45: E1231 | EA45: E132 | EB45: E133 | EC45: E134 | ED45: E135 | EE45: E141 | EF45: E142 | EG45: E143 | EH45: E144 | EI45: E145 | EJ45: E151 | EK45: E152 | EL45: E153 | EM45: E154 | EN45: E155 | EO45: E161 | EP45: E162 | EQ45: E163 | ER45: E164 | ES45: E165 | ET45: E171 | EU45: E172 | EV45: E173 | EW45: E174 | EX45: E175 | EY45: E181 | EZ45: E182 | FA45: E183
BF46: 1 | BG46: 2 | BH46: 3 | BI46: 4 | BJ46: 5 | BK46: 6 | BL46: 7 | BM46: 8 | BN46: 9 | BO46: 10 | BP46: 11 | BQ46: 12 | BR46: 13 | BS46: 14 | BT46: 15 | BU46: 16 | BV46: 17 | BW46: 18 | BX46: 19 | BY46: 20 | BZ46: 21 | CA46: 22 | CB46: 23 | CE46: 24 | CF46: 25 | CG46: 26 | CH46: 27 | CI46: 28 | CJ46: 29 | CK46: 30 | CL46: 31 | CM46: 32 | CN46: 33 | CO46: 34 | CP46: 35 | CQ46: 36 | CS46: 37 | CT46: 38 | CU46: 39 | CV46: 40 | CW46: 41 | CY46: 42 | CZ46: 43 | DA46: 44 | DB46: 45 | DC46: 46 | DD46: 47 | DE46: 48 | DF46: 49 | DG46: 50 | DH46: 51 | DI46: 52 | DJ46: 53 | DK46: 54 | DL46: 55 | DM46: 56 | DN46: 57 | DO46: 58 | DP46: 59 | DQ46: 60 | DR46: 61 | DS46: 62 | DT46: 63 | DU46: 64 | DV46: 65 | DW46: 66 | DX46: 67 | DY46: 68 | DZ46: 69 | EA46: 70 | EB46: 71 | EC46: 72 | ED46: 73 | EE46: 74 | EF46: 75 | EG46: 76 | EH46: 77 | EI46: 78 | EJ46: 79 | EK46: 80 | EL46: 81 | EM46: 82 | EN46: 83 | EO46: 84 | EP46: 85 | EQ46: 86 | ER46: 87 | ES46: 88 | ET46: 89 | EU46: 90 | EV46: 91 | EW46: 92 | EX46: 93 | EY46: 94 | EZ46: 95 | FA46: 96
...
